Workbook
Name Supermercado: Jan!$D$6
Name Janeiro: #REF!
Name A4_: Jan!$D$6

Sheet Jan
C1: Orçamento Doméstico
B2: Descritivo de Receitas e Despesas realizadas | F2: Janeiro | H2: =+'Instruções'!$I$19 -> #REF! | J2: Movimentação do saldo no mês
H3: Meio de pagamento | J3: Saldo do mês anterior
B4: Grupo de conta | C4: Sub-grupo de conta | D4: Cod. | E4: Data | F4: Descritivo | G4: Valor R$ | J4: C.Corrente (+ / -) | K4: Dinheiro (+ / -) | L4: C. de Crédito (+)
A6: 1 | B6: =IF(IF(ISERROR(VLOOKUP(D6,Categorias!$B$4:$C$65,2,FALSE)),"",VLOOKUP(D6,Categorias!$B$4:$C$65,2,FALSE))=D6,"",VLOOKUP(D6,(Categorias!$B$4:$C$65),2,FALSE)) | C6: =IF(IF(ISERROR(VLOOKUP(D6,Categorias!$B$4:$C$65,2,FALSE)),"",VLOOKUP(D6,Categorias!$B$4:$C$65,2,FALSE))=D6,"",VLOOKUP(D6,(Categorias!$B$2:$D$65),3,FALSE)) | J6: =IF(H6="",(""),IF(H6="DP",(J5+G6),IF(H6="DB",(J5-G6),IF(H6="TR",(J5-G6),IF(H6="CH",(J5-G6),IF(H6="SQ",(J5-G6),J5)))))) | K6: =IF(H6="",(""),IF(H6="SQ",(K5+G6),IF(H6="RD",(K5+G6),IF(H6="DI",(K5-G6),K5)))) | L6: =IF(H6="",(""),IF(H6="CC",(L5+G6),IF(H6="PC",(L5+G6),L5)))
B7: =IF(IF(ISERROR(VLOOKUP(D7,Categorias!$B$4:$C$65,2,FALSE)),"",VLOOKUP(D7,Categorias!$B$4:$C$65,2,FALSE))=D7,"",VLOOKUP(D7,(Categorias!$B$4:$C$65),2,FALSE)) | C7: =IF(IF(ISERROR(VLOOKUP(D7,Categorias!$B$4:$C$65,2,FALSE)),"",VLOOKUP(D7,Categorias!$B$4:$C$65,2,FALSE))=D7,"",VLOOKUP(D7,(Categorias!$B$2:$D$65),3,FALSE)) | J7: =IF(H7="",(""),IF(H7="DP",(J6+G7),IF(H7="DB",(J6-G7),IF(H7="TR",(J6-G7),IF(H7="CH",(J6-G7),IF(H7="SQ",(J6-G7),J6)))))) | K7: =IF(H7="",(""),IF(H7="SQ",(K6+G7),IF(H7="RD",(K6+G7),IF(H7="DI",(K6-G7),K6)))) | L7: =IF(H7="",(""),IF(H7="CC",(L6+G7),IF(H7="PC",(L6+G7),L6)))
B8: =IF(IF(ISERROR(VLOOKUP(D8,Categorias!$B$4:$C$65,2,FALSE)),"",VLOOKUP(D8,Categorias!$B$4:$C$65,2,FALSE))=D8,"",VLOOKUP(D8,(Categorias!$B$4:$C$65),2,FALSE)) | C8: =IF(IF(ISERROR(VLOOKUP(D8,Categorias!$B$4:$C$65,2,FALSE)),"",VLOOKUP(D8,Categorias!$B$4:$C$65,2,FALSE))=D8,"",VLOOKUP(D8,(Categorias!$B$2:$D$65),3,FALSE)) | J8: =IF(H8="",(""),IF(H8="DP",(J7+G8),IF(H8="DB",(J7-G8),IF(H8="TR",(J7-G8),IF(H8="CH",(J7-G8),IF(H8="SQ",(J7-G8),J7)))))) | K8: =IF(H8="",(""),IF(H8="SQ",(K7+G8),IF(H8="RD",(K7+G8),IF(H8="DI",(K7-G8),K7)))) | L8: =IF(H8="",(""),IF(H8="CC",(L7+G8),IF(H8="PC",(L7+G8),L7)))
B9: =IF(IF(ISERROR(VLOOKUP(D9,Categorias!$B$4:$C$65,2,FALSE)),"",VLOOKUP(D9,Categorias!$B$4:$C$65,2,FALSE))=D9,"",VLOOKUP(D9,(Categorias!$B$4:$C$65),2,FALSE)) | C9: =IF(IF(ISERROR(VLOOKUP(D9,Categorias!$B$4:$C$65,2,FALSE)),"",VLOOKUP(D9,Categorias!$B$4:$C$65,2,FALSE))=D9,"",VLOOKUP(D9,(Categorias!$B$2:$D$65),3,FALSE)) | J9: =IF(H9="",(""),IF(H9="DP",(J8+G9),IF(H9="DB",(J8-G9),IF(H9="TR",(J8-G9),IF(H9="CH",(J8-G9),IF(H9="SQ",(J8-G9),J8)))))) | K9: =IF(H9="",(""),IF(H9="SQ",(K8+G9),IF(H9="RD",(K8+G9),IF(H9="DI",(K8-G9),K8)))) | L9: =IF(H9="",(""),IF(H9="CC",(L8+G9),IF(H9="PC",(L8+G9),L8)))
B10: =IF(IF(ISERROR(VLOOKUP(D10,Categorias!$B$4:$C$65,2,FALSE)),"",VLOOKUP(D10,Categorias!$B$4:$C$65,2,FALSE))=D10,"",VLOOKUP(D10,(Categorias!$B$4:$C$65),2,FALSE)) | C10: =IF(IF(ISERROR(VLOOKUP(D10,Categorias!$B$4:$C$65,2,FALSE)),"",VLOOKUP(D10,Categorias!$B$4:$C$65,2,FALSE))=D10,"",VLOOKUP(D10,(Categorias!$B$2:$D$65),3,FALSE)) | J10: =IF(H10="",(""),IF(H10="DP",(J9+G10),IF(H10="DB",(J9-G10),IF(H10="TR",(J9-G10),IF(H10="CH",(J9-G10),IF(H10="SQ",(J9-G10),J9)))))) | K10: =IF(H10="",(""),IF(H10="SQ",(K9+G10),IF(H10="RD",(K9+G10),IF(H10="DI",(K9-G10),K9)))) | L10: =IF(H10="",(""),IF(H10="CC",(L9+G10),IF(H10="PC",(L9+G10),L9)))
B11: =IF(IF(ISERROR(VLOOKUP(D11,Categorias!$B$4:$C$65,2,FALSE)),"",VLOOKUP(D11,Categorias!$B$4:$C$65,2,FALSE))=D11,"",VLOOKUP(D11,(Categorias!$B$4:$C$65),2,FALSE)) | C11: =IF(IF(ISERROR(VLOOKUP(D11,Categorias!$B$4:$C$65,2,FALSE)),"",VLOOKUP(D11,Categorias!$B$4:$C$65,2,FALSE))=D11,"",VLOOKUP(D11,(Categorias!$B$2:$D$65),3,FALSE)) | J11: =IF(H11="",(""),IF(H11="DP",(J10+G11),IF(H11="DB",(J10-G11),IF(H11="TR",(J10-G11),IF(H11="CH",(J10-G11),IF(H11="SQ",(J10-G11),J10)))))) | K11: =IF(H11="",(""),IF(H11="SQ",(K10+G11),IF(H11="RD",(K10+G11),IF(H11="DI",(K10-G11),K10)))) | L11: =IF(H11="",(""),IF(H11="CC",(L10+G11),IF(H11="PC",(L10+G11),L10)))
B12: =IF(IF(ISERROR(VLOOKUP(D12,Categorias!$B$4:$C$65,2,FALSE)),"",VLOOKUP(D12,Categorias!$B$4:$C$65,2,FALSE))=D12,"",VLOOKUP(D12,(Categorias!$B$4:$C$65),2,FALSE)) | C12: =IF(IF(ISERROR(VLOOKUP(D12,Categorias!$B$4:$C$65,2,FALSE)),"",VLOOKUP(D12,Categorias!$B$4:$C$65,2,FALSE))=D12,"",VLOOKUP(D12,(Categorias!$B$2:$D$65),3,FALSE)) | J12: =IF(H12="",(""),IF(H12="DP",(J11+G12),IF(H12="DB",(J11-G12),IF(H12="TR",(J11-G12),IF(H12="CH",(J11-G12),IF(H12="SQ",(J11-G12),J11)))))) | K12: =IF(H12="",(""),IF(H12="SQ",(K11+G12),IF(H12="RD",(K11+G12),IF(H12="DI",(K11-G12),K11)))) | L12: =IF(H12="",(""),IF(H12="CC",(L11+G12),IF(H12="PC",(L11+G12),L11)))
B13: =IF(IF(ISERROR(VLOOKUP(D13,Categorias!$B$4:$C$65,2,FALSE)),"",VLOOKUP(D13,Categorias!$B$4:$C$65,2,FALSE))=D13,"",VLOOKUP(D13,(Categorias!$B$4:$C$65),2,FALSE)) | C13: =IF(IF(ISERROR(VLOOKUP(D13,Categorias!$B$4:$C$65,2,FALSE)),"",VLOOKUP(D13,Categorias!$B$4:$C$65,2,FALSE))=D13,"",VLOOKUP(D13,(Categorias!$B$2:$D$65),3,FALSE)) | J13: =IF(H13="",(""),IF(H13="DP",(J12+G13),IF(H13="DB",(J12-G13),IF(H13="TR",(J12-G13),IF(H13="CH",(J12-G13),IF(H13="SQ",(J12-G13),J12)))))) | K13: =IF(H13="",(""),IF(H13="SQ",(K12+G13),IF(H13="RD",(K12+G13),IF(H13="DI",(K12-G13),K12)))) | L13: =IF(H13="",(""),IF(H13="CC",(L12+G13),IF(H13="PC",(L12+G13),L12)))
B14: =IF(IF(ISERROR(VLOOKUP(D14,Categorias!$B$4:$C$65,2,FALSE)),"",VLOOKUP(D14,Categorias!$B$4:$C$65,2,FALSE))=D14,"",VLOOKUP(D14,(Categorias!$B$4:$C$65),2,FALSE)) | C14: =IF(IF(ISERROR(VLOOKUP(D14,Categorias!$B$4:$C$65,2,FALSE)),"",VLOOKUP(D14,Categorias!$B$4:$C$65,2,FALSE))=D14,"",VLOOKUP(D14,(Categorias!$B$2:$D$65),3,FALSE)) | J14: =IF(H14="",(""),IF(H14="DP",(J13+G14),IF(H14="DB",(J13-G14),IF(H14="TR",(J13-G14),IF(H14="CH",(J13-G14),IF(H14="SQ",(J13-G14),J13)))))) | K14: =IF(H14="",(""),IF(H14="SQ",(K13+G14),IF(H14="RD",(K13+G14),IF(H14="DI",(K13-G14),K13)))) | L14: =IF(H14="",(""),IF(H14="CC",(L13+G14),IF(H14="PC",(L13+G14),L13)))
B15: =IF(IF(ISERROR(VLOOKUP(D15,Categorias!$B$4:$C$65,2,FALSE)),"",VLOOKUP(D15,Categorias!$B$4:$C$65,2,FALSE))=D15,"",VLOOKUP(D15,(Categorias!$B$4:$C$65),2,FALSE)) | C15: =IF(IF(ISERROR(VLOOKUP(D15,Categorias!$B$4:$C$65,2,FALSE)),"",VLOOKUP(D15,Categorias!$B$4:$C$65,2,FALSE))=D15,"",VLOOKUP(D15,(Categorias!$B$2:$D$65),3,FALSE)) | J15: =IF(H15="",(""),IF(H15="DP",(J14+G15),IF(H15="DB",(J14-G15),IF(H15="TR",(J14-G15),IF(H15="CH",(J14-G15),IF(H15="SQ",(J14-G15),J14)))))) | K15: =IF(H15="",(""),IF(H15="SQ",(K14+G15),IF(H15="RD",(K14+G15),IF(H15="DI",(K14-G15),K14)))) | L15: =IF(H15="",(""),IF(H15="CC",(L14+G15),IF(H15="PC",(L14+G15),L14)))
B16: =IF(IF(ISERROR(VLOOKUP(D16,Categorias!$B$4:$C$65,2,FALSE)),"",VLOOKUP(D16,Categorias!$B$4:$C$65,2,FALSE))=D16,"",VLOOKUP(D16,(Categorias!$B$4:$C$65),2,FALSE)) | C16: =IF(IF(ISERROR(VLOOKUP(D16,Categorias!$B$4:$C$65,2,FALSE)),"",VLOOKUP(D16,Categorias!$B$4:$C$65,2,FALSE))=D16,"",VLOOKUP(D16,(Categorias!$B$2:$D$65),3,FALSE)) | J16: =IF(H16="",(""),IF(H16="DP",(J15+G16),IF(H16="DB",(J15-G16),IF(H16="TR",(J15-G16),IF(H16="CH",(J15-G16),IF(H16="SQ",(J15-G16),J15)))))) | K16: =IF(H16="",(""),IF(H16="SQ",(K15+G16),IF(H16="RD",(K15+G16),IF(H16="DI",(K15-G16),K15)))) | L16: =IF(H16="",(""),IF(H16="CC",(L15+G16),IF(H16="PC",(L15+G16),L15)))
B17: =IF(IF(ISERROR(VLOOKUP(D17,Categorias!$B$4:$C$65,2,FALSE)),"",VLOOKUP(D17,Categorias!$B$4:$C$65,2,FALSE))=D17,"",VLOOKUP(D17,(Categorias!$B$4:$C$65),2,FALSE)) | C17: =IF(IF(ISERROR(VLOOKUP(D17,Categorias!$B$4:$C$65,2,FALSE)),"",VLOOKUP(D17,Categorias!$B$4:$C$65,2,FALSE))=D17,"",VLOOKUP(D17,(Categorias!$B$2:$D$65),3,FALSE)) | J17: =IF(H17="",(""),IF(H17="DP",(J16+G17),IF(H17="DB",(J16-G17),IF(H17="TR",(J16-G17),IF(H17="CH",(J16-G17),IF(H17="SQ",(J16-G17),J16)))))) | K17: =IF(H17="",(""),IF(H17="SQ",(K16+G17),IF(H17="RD",(K16+G17),IF(H17="DI",(K16-G17),K16)))) | L17: =IF(H17="",(""),IF(H17="CC",(L16+G17),IF(H17="PC",(L16+G17),L16)))
B18: =IF(IF(ISERROR(VLOOKUP(D18,Categorias!$B$4:$C$65,2,FALSE)),"",VLOOKUP(D18,Categorias!$B$4:$C$65,2,FALSE))=D18,"",VLOOKUP(D18,(Categorias!$B$4:$C$65),2,FALSE)) | C18: =IF(IF(ISERROR(VLOOKUP(D18,Categorias!$B$4:$C$65,2,FALSE)),"",VLOOKUP(D18,Categorias!$B$4:$C$65,2,FALSE))=D18,"",VLOOKUP(D18,(Categorias!$B$2:$D$65),3,FALSE)) | J18: =IF(H18="",(""),IF(H18="DP",(J17+G18),IF(H18="DB",(J17-G18),IF(H18="TR",(J17-G18),IF(H18="CH",(J17-G18),IF(H18="SQ",(J17-G18),J17)))))) | K18: =IF(H18="",(""),IF(H18="SQ",(K17+G18),IF(H18="RD",(K17+G18),IF(H18="DI",(K17-G18),K17)))) | L18: =IF(H18="",(""),IF(H18="CC",(L17+G18),IF(H18="PC",(L17+G18),L17)))
... B75: =IF(IF(ISERROR(VLOOKUP(D75,Categorias!$B$4:$C$65,2,FALSE)),"",VLOOKUP(D75,Categorias!$B$4:$C$65,2,FALSE))=D75,"",VLOOKUP(D75,(Categorias!$B$4:$C$65),2,FALSE)) | C75: =IF(IF(ISERROR(VLOOKUP(D75,Categorias!$B$4:$C$65,2,FALSE)),"",VLOOKUP(D75,Categorias!$B$4:$C$65,2,FALSE))=D75,"",VLOOKUP(D75,(Categorias!$B$2:$D$65),3,FALSE)) | J75: =IF(H75="",(""),IF(H75="DP",(J74+G75),IF(H75="DB",(J74-G75),IF(H75="TR",(J74-G75),IF(H75="CH",(J74-G75),IF(H75="SQ",(J74-G75),J74)))))) | K75: =IF(H75="",(""),IF(H75="SQ",(K74+G75),IF(H75="RD",(K74+G75),IF(H75="DI",(K74-G75),K74)))) | L75: =IF(H75="",(""),IF(H75="CC",(L74+G75),IF(H75="PC",(L74+G75),L74)))
F76: Saldo no mês | J76: =+J75 | K76: =+K75 | L76: =+L75
A213: 1
A214: 1

Sheet Fev
C1: Orçamento Doméstico
B2: Descritivo de Receitas e Despesas realizadas | F2: Fevereiro | H2: =+'Instruções'!$I$19 -> #REF! | J2: Movimentação do saldo no mês
H3: Meio de pagamento | J3: Saldo do mês anterior
B4: Grupo de conta | C4: Sub-grupo de conta | D4: Cod. | E4: Data | F4: Descritivo | G4: Valor R$ | J4: C.Corrente (+ / -) | K4: Dinheiro (+ / -) | L4: C. de Crédito (+)
A6: 1 | B6: =IF(IF(ISERROR(VLOOKUP(D6,Categorias!$B$4:$C$65,2,FALSE)),"",VLOOKUP(D6,Categorias!$B$4:$C$65,2,FALSE))=D6,"",VLOOKUP(D6,(Categorias!$B$4:$C$65),2,FALSE)) | C6: =IF(IF(ISERROR(VLOOKUP(D6,Categorias!$B$4:$C$65,2,FALSE)),"",VLOOKUP(D6,Categorias!$B$4:$C$65,2,FALSE))=D6,"",VLOOKUP(D6,(Categorias!$B$2:$D$65),3,FALSE)) | J6: =IF(H6="",(""),IF(H6="DP",(J5+G6),IF(H6="DB",(J5-G6),IF(H6="TR",(J5-G6),IF(H6="CH",(J5-G6),IF(H6="SQ",(J5-G6),J5)))))) | K6: =IF(H6="",(""),IF(H6="SQ",(K5+G6),IF(H6="RD",(K5+G6),IF(H6="DI",(K5-G6),K5)))) | L6: =IF(H6="",(""),IF(H6="CC",(L5+G6),IF(H6="PC",(L5+G6),L5)))
B7: =IF(IF(ISERROR(VLOOKUP(D7,Categorias!$B$4:$C$65,2,FALSE)),"",VLOOKUP(D7,Categorias!$B$4:$C$65,2,FALSE))=D7,"",VLOOKUP(D7,(Categorias!$B$4:$C$65),2,FALSE)) | C7: =IF(IF(ISERROR(VLOOKUP(D7,Categorias!$B$4:$C$65,2,FALSE)),"",VLOOKUP(D7,Categorias!$B$4:$C$65,2,FALSE))=D7,"",VLOOKUP(D7,(Categorias!$B$2:$D$65),3,FALSE)) | J7: =IF(H7="",(""),IF(H7="DP",(J6+G7),IF(H7="DB",(J6-G7),IF(H7="TR",(J6-G7),IF(H7="CH",(J6-G7),IF(H7="SQ",(J6-G7),J6)))))) | K7: =IF(H7="",(""),IF(H7="SQ",(K6+G7),IF(H7="RD",(K6+G7),IF(H7="DI",(K6-G7),K6)))) | L7: =IF(H7="",(""),IF(H7="CC",(L6+G7),IF(H7="PC",(L6+G7),L6)))
B8: =IF(IF(ISERROR(VLOOKUP(D8,Categorias!$B$4:$C$65,2,FALSE)),"",VLOOKUP(D8,Categorias!$B$4:$C$65,2,FALSE))=D8,"",VLOOKUP(D8,(Categorias!$B$4:$C$65),2,FALSE)) | C8: =IF(IF(ISERROR(VLOOKUP(D8,Categorias!$B$4:$C$65,2,FALSE)),"",VLOOKUP(D8,Categorias!$B$4:$C$65,2,FALSE))=D8,"",VLOOKUP(D8,(Categorias!$B$2:$D$65),3,FALSE)) | J8: =IF(H8="",(""),IF(H8="DP",(J7+G8),IF(H8="DB",(J7-G8),IF(H8="TR",(J7-G8),IF(H8="CH",(J7-G8),IF(H8="SQ",(J7-G8),J7)))))) | K8: =IF(H8="",(""),IF(H8="SQ",(K7+G8),IF(H8="RD",(K7+G8),IF(H8="DI",(K7-G8),K7)))) | L8: =IF(H8="",(""),IF(H8="CC",(L7+G8),IF(H8="PC",(L7+G8),L7)))
B9: =IF(IF(ISERROR(VLOOKUP(D9,Categorias!$B$4:$C$65,2,FALSE)),"",VLOOKUP(D9,Categorias!$B$4:$C$65,2,FALSE))=D9,"",VLOOKUP(D9,(Categorias!$B$4:$C$65),2,FALSE)) | C9: =IF(IF(ISERROR(VLOOKUP(D9,Categorias!$B$4:$C$65,2,FALSE)),"",VLOOKUP(D9,Categorias!$B$4:$C$65,2,FALSE))=D9,"",VLOOKUP(D9,(Categorias!$B$2:$D$65),3,FALSE)) | J9: =IF(H9="",(""),IF(H9="DP",(J8+G9),IF(H9="DB",(J8-G9),IF(H9="TR",(J8-G9),IF(H9="CH",(J8-G9),IF(H9="SQ",(J8-G9),J8)))))) | K9: =IF(H9="",(""),IF(H9="SQ",(K8+G9),IF(H9="RD",(K8+G9),IF(H9="DI",(K8-G9),K8)))) | L9: =IF(H9="",(""),IF(H9="CC",(L8+G9),IF(H9="PC",(L8+G9),L8)))
B10: =IF(IF(ISERROR(VLOOKUP(D10,Categorias!$B$4:$C$65,2,FALSE)),"",VLOOKUP(D10,Categorias!$B$4:$C$65,2,FALSE))=D10,"",VLOOKUP(D10,(Categorias!$B$4:$C$65),2,FALSE)) | C10: =IF(IF(ISERROR(VLOOKUP(D10,Categorias!$B$4:$C$65,2,FALSE)),"",VLOOKUP(D10,Categorias!$B$4:$C$65,2,FALSE))=D10,"",VLOOKUP(D10,(Categorias!$B$2:$D$65),3,FALSE)) | J10: =IF(H10="",(""),IF(H10="DP",(J9+G10),IF(H10="DB",(J9-G10),IF(H10="TR",(J9-G10),IF(H10="CH",(J9-G10),IF(H10="SQ",(J9-G10),J9)))))) | K10: =IF(H10="",(""),IF(H10="SQ",(K9+G10),IF(H10="RD",(K9+G10),IF(H10="DI",(K9-G10),K9)))) | L10: =IF(H10="",(""),IF(H10="CC",(L9+G10),IF(H10="PC",(L9+G10),L9)))
B11: =IF(IF(ISERROR(VLOOKUP(D11,Categorias!$B$4:$C$65,2,FALSE)),"",VLOOKUP(D11,Categorias!$B$4:$C$65,2,FALSE))=D11,"",VLOOKUP(D11,(Categorias!$B$4:$C$65),2,FALSE)) | C11: =IF(IF(ISERROR(VLOOKUP(D11,Categorias!$B$4:$C$65,2,FALSE)),"",VLOOKUP(D11,Categorias!$B$4:$C$65,2,FALSE))=D11,"",VLOOKUP(D11,(Categorias!$B$2:$D$65),3,FALSE)) | J11: =IF(H11="",(""),IF(H11="DP",(J10+G11),IF(H11="DB",(J10-G11),IF(H11="TR",(J10-G11),IF(H11="CH",(J10-G11),IF(H11="SQ",(J10-G11),J10)))))) | K11: =IF(H11="",(""),IF(H11="SQ",(K10+G11),IF(H11="RD",(K10+G11),IF(H11="DI",(K10-G11),K10)))) | L11: =IF(H11="",(""),IF(H11="CC",(L10+G11),IF(H11="PC",(L10+G11),L10)))
B12: =IF(IF(ISERROR(VLOOKUP(D12,Categorias!$B$4:$C$65,2,FALSE)),"",VLOOKUP(D12,Categorias!$B$4:$C$65,2,FALSE))=D12,"",VLOOKUP(D12,(Categorias!$B$4:$C$65),2,FALSE)) | C12: =IF(IF(ISERROR(VLOOKUP(D12,Categorias!$B$4:$C$65,2,FALSE)),"",VLOOKUP(D12,Categorias!$B$4:$C$65,2,FALSE))=D12,"",VLOOKUP(D12,(Categorias!$B$2:$D$65),3,FALSE)) | J12: =IF(H12="",(""),IF(H12="DP",(J11+G12),IF(H12="DB",(J11-G12),IF(H12="TR",(J11-G12),IF(H12="CH",(J11-G12),IF(H12="SQ",(J11-G12),J11)))))) | K12: =IF(H12="",(""),IF(H12="SQ",(K11+G12),IF(H12="RD",(K11+G12),IF(H12="DI",(K11-G12),K11)))) | L12: =IF(H12="",(""),IF(H12="CC",(L11+G12),IF(H12="PC",(L11+G12),L11)))
B13: =IF(IF(ISERROR(VLOOKUP(D13,Categorias!$B$4:$C$65,2,FALSE)),"",VLOOKUP(D13,Categorias!$B$4:$C$65,2,FALSE))=D13,"",VLOOKUP(D13,(Categorias!$B$4:$C$65),2,FALSE)) | C13: =IF(IF(ISERROR(VLOOKUP(D13,Categorias!$B$4:$C$65,2,FALSE)),"",VLOOKUP(D13,Categorias!$B$4:$C$65,2,FALSE))=D13,"",VLOOKUP(D13,(Categorias!$B$2:$D$65),3,FALSE)) | J13: =IF(H13="",(""),IF(H13="DP",(J12+G13),IF(H13="DB",(J12-G13),IF(H13="TR",(J12-G13),IF(H13="CH",(J12-G13),IF(H13="SQ",(J12-G13),J12)))))) | K13: =IF(H13="",(""),IF(H13="SQ",(K12+G13),IF(H13="RD",(K12+G13),IF(H13="DI",(K12-G13),K12)))) | L13: =IF(H13="",(""),IF(H13="CC",(L12+G13),IF(H13="PC",(L12+G13),L12)))
B14: =IF(IF(ISERROR(VLOOKUP(D14,Categorias!$B$4:$C$65,2,FALSE)),"",VLOOKUP(D14,Categorias!$B$4:$C$65,2,FALSE))=D14,"",VLOOKUP(D14,(Categorias!$B$4:$C$65),2,FALSE)) | C14: =IF(IF(ISERROR(VLOOKUP(D14,Categorias!$B$4:$C$65,2,FALSE)),"",VLOOKUP(D14,Categorias!$B$4:$C$65,2,FALSE))=D14,"",VLOOKUP(D14,(Categorias!$B$2:$D$65),3,FALSE)) | J14: =IF(H14="",(""),IF(H14="DP",(J13+G14),IF(H14="DB",(J13-G14),IF(H14="TR",(J13-G14),IF(H14="CH",(J13-G14),IF(H14="SQ",(J13-G14),J13)))))) | K14: =IF(H14="",(""),IF(H14="SQ",(K13+G14),IF(H14="RD",(K13+G14),IF(H14="DI",(K13-G14),K13)))) | L14: =IF(H14="",(""),IF(H14="CC",(L13+G14),IF(H14="PC",(L13+G14),L13)))
B15: =IF(IF(ISERROR(VLOOKUP(D15,Categorias!$B$4:$C$65,2,FALSE)),"",VLOOKUP(D15,Categorias!$B$4:$C$65,2,FALSE))=D15,"",VLOOKUP(D15,(Categorias!$B$4:$C$65),2,FALSE)) | C15: =IF(IF(ISERROR(VLOOKUP(D15,Categorias!$B$4:$C$65,2,FALSE)),"",VLOOKUP(D15,Categorias!$B$4:$C$65,2,FALSE))=D15,"",VLOOKUP(D15,(Categorias!$B$2:$D$65),3,FALSE)) | J15: =IF(H15="",(""),IF(H15="DP",(J14+G15),IF(H15="DB",(J14-G15),IF(H15="TR",(J14-G15),IF(H15="CH",(J14-G15),IF(H15="SQ",(J14-G15),J14)))))) | K15: =IF(H15="",(""),IF(H15="SQ",(K14+G15),IF(H15="RD",(K14+G15),IF(H15="DI",(K14-G15),K14)))) | L15: =IF(H15="",(""),IF(H15="CC",(L14+G15),IF(H15="PC",(L14+G15),L14)))
B16: =IF(IF(ISERROR(VLOOKUP(D16,Categorias!$B$4:$C$65,2,FALSE)),"",VLOOKUP(D16,Categorias!$B$4:$C$65,2,FALSE))=D16,"",VLOOKUP(D16,(Categorias!$B$4:$C$65),2,FALSE)) | C16: =IF(IF(ISERROR(VLOOKUP(D16,Categorias!$B$4:$C$65,2,FALSE)),"",VLOOKUP(D16,Categorias!$B$4:$C$65,2,FALSE))=D16,"",VLOOKUP(D16,(Categorias!$B$2:$D$65),3,FALSE)) | J16: =IF(H16="",(""),IF(H16="DP",(J15+G16),IF(H16="DB",(J15-G16),IF(H16="TR",(J15-G16),IF(H16="CH",(J15-G16),IF(H16="SQ",(J15-G16),J15)))))) | K16: =IF(H16="",(""),IF(H16="SQ",(K15+G16),IF(H16="RD",(K15+G16),IF(H16="DI",(K15-G16),K15)))) | L16: =IF(H16="",(""),IF(H16="CC",(L15+G16),IF(H16="PC",(L15+G16),L15)))
B17: =IF(IF(ISERROR(VLOOKUP(D17,Categorias!$B$4:$C$65,2,FALSE)),"",VLOOKUP(D17,Categorias!$B$4:$C$65,2,FALSE))=D17,"",VLOOKUP(D17,(Categorias!$B$4:$C$65),2,FALSE)) | C17: =IF(IF(ISERROR(VLOOKUP(D17,Categorias!$B$4:$C$65,2,FALSE)),"",VLOOKUP(D17,Categorias!$B$4:$C$65,2,FALSE))=D17,"",VLOOKUP(D17,(Categorias!$B$2:$D$65),3,FALSE)) | J17: =IF(H17="",(""),IF(H17="DP",(J16+G17),IF(H17="DB",(J16-G17),IF(H17="TR",(J16-G17),IF(H17="CH",(J16-G17),IF(H17="SQ",(J16-G17),J16)))))) | K17: =IF(H17="",(""),IF(H17="SQ",(K16+G17),IF(H17="RD",(K16+G17),IF(H17="DI",(K16-G17),K16)))) | L17: =IF(H17="",(""),IF(H17="CC",(L16+G17),IF(H17="PC",(L16+G17),L16)))
B18: =IF(IF(ISERROR(VLOOKUP(D18,Categorias!$B$4:$C$65,2,FALSE)),"",VLOOKUP(D18,Categorias!$B$4:$C$65,2,FALSE))=D18,"",VLOOKUP(D18,(Categorias!$B$4:$C$65),2,FALSE)) | C18: =IF(IF(ISERROR(VLOOKUP(D18,Categorias!$B$4:$C$65,2,FALSE)),"",VLOOKUP(D18,Categorias!$B$4:$C$65,2,FALSE))=D18,"",VLOOKUP(D18,(Categorias!$B$2:$D$65),3,FALSE)) | J18: =IF(H18="",(""),IF(H18="DP",(J17+G18),IF(H18="DB",(J17-G18),IF(H18="TR",(J17-G18),IF(H18="CH",(J17-G18),IF(H18="SQ",(J17-G18),J17)))))) | K18: =IF(H18="",(""),IF(H18="SQ",(K17+G18),IF(H18="RD",(K17+G18),IF(H18="DI",(K17-G18),K17)))) | L18: =IF(H18="",(""),IF(H18="CC",(L17+G18),IF(H18="PC",(L17+G18),L17)))
... B75: =IF(IF(ISERROR(VLOOKUP(D75,Categorias!$B$4:$C$65,2,FALSE)),"",VLOOKUP(D75,Categorias!$B$4:$C$65,2,FALSE))=D75,"",VLOOKUP(D75,(Categorias!$B$4:$C$65),2,FALSE)) | C75: =IF(IF(ISERROR(VLOOKUP(D75,Categorias!$B$4:$C$65,2,FALSE)),"",VLOOKUP(D75,Categorias!$B$4:$C$65,2,FALSE))=D75,"",VLOOKUP(D75,(Categorias!$B$2:$D$65),3,FALSE)) | J75: =IF(H75="",(""),IF(H75="DP",(J74+G75),IF(H75="DB",(J74-G75),IF(H75="TR",(J74-G75),IF(H75="CH",(J74-G75),IF(H75="SQ",(J74-G75),J74)))))) | K75: =IF(H75="",(""),IF(H75="SQ",(K74+G75),IF(H75="RD",(K74+G75),IF(H75="DI",(K74-G75),K74)))) | L75: =IF(H75="",(""),IF(H75="CC",(L74+G75),IF(H75="PC",(L74+G75),L74)))
F76: Saldo no mês | J76: =+J75 | K76: =+K75 | L76: =+L75
A213: 1
A214: 1

Sheet Mar
C1: Orçamento Doméstico
B2: Descritivo de Receitas e Despesas realizadas | F2: Março | H2: =+'Instruções'!$I$19 -> #REF! | J2: Movimentação do saldo no mês
H3: Meio de pagamento | J3: Saldo do mês anterior
B4: Grupo de conta | C4: Sub-grupo de conta | D4: Cod. | E4: Data | F4: Descritivo | G4: Valor R$ | J4: C.Corrente (+ / -) | K4: Dinheiro (+ / -) | L4: C. de Crédito (+)
A6: 1 | B6: =IF(IF(ISERROR(VLOOKUP(D6,Categorias!$B$4:$C$65,2,FALSE)),"",VLOOKUP(D6,Categorias!$B$4:$C$65,2,FALSE))=D6,"",VLOOKUP(D6,(Categorias!$B$4:$C$65),2,FALSE)) | C6: =IF(IF(ISERROR(VLOOKUP(D6,Categorias!$B$4:$C$65,2,FALSE)),"",VLOOKUP(D6,Categorias!$B$4:$C$65,2,FALSE))=D6,"",VLOOKUP(D6,(Categorias!$B$2:$D$65),3,FALSE)) | J6: =IF(H6="",(""),IF(H6="DP",(J5+G6),IF(H6="DB",(J5-G6),IF(H6="TR",(J5-G6),IF(H6="CH",(J5-G6),IF(H6="SQ",(J5-G6),J5)))))) | K6: =IF(H6="",(""),IF(H6="SQ",(K5+G6),IF(H6="RD",(K5+G6),IF(H6="DI",(K5-G6),K5)))) | L6: =IF(H6="",(""),IF(H6="CC",(L5+G6),IF(H6="PC",(L5+G6),L5)))
B7: =IF(IF(ISERROR(VLOOKUP(D7,Categorias!$B$4:$C$65,2,FALSE)),"",VLOOKUP(D7,Categorias!$B$4:$C$65,2,FALSE))=D7,"",VLOOKUP(D7,(Categorias!$B$4:$C$65),2,FALSE)) | C7: =IF(IF(ISERROR(VLOOKUP(D7,Categorias!$B$4:$C$65,2,FALSE)),"",VLOOKUP(D7,Categorias!$B$4:$C$65,2,FALSE))=D7,"",VLOOKUP(D7,(Categorias!$B$2:$D$65),3,FALSE)) | J7: =IF(H7="",(""),IF(H7="DP",(J6+G7),IF(H7="DB",(J6-G7),IF(H7="TR",(J6-G7),IF(H7="CH",(J6-G7),IF(H7="SQ",(J6-G7),J6)))))) | K7: =IF(H7="",(""),IF(H7="SQ",(K6+G7),IF(H7="RD",(K6+G7),IF(H7="DI",(K6-G7),K6)))) | L7: =IF(H7="",(""),IF(H7="CC",(L6+G7),IF(H7="PC",(L6+G7),L6)))
B8: =IF(IF(ISERROR(VLOOKUP(D8,Categorias!$B$4:$C$65,2,FALSE)),"",VLOOKUP(D8,Categorias!$B$4:$C$65,2,FALSE))=D8,"",VLOOKUP(D8,(Categorias!$B$4:$C$65),2,FALSE)) | C8: =IF(IF(ISERROR(VLOOKUP(D8,Categorias!$B$4:$C$65,2,FALSE)),"",VLOOKUP(D8,Categorias!$B$4:$C$65,2,FALSE))=D8,"",VLOOKUP(D8,(Categorias!$B$2:$D$65),3,FALSE)) | J8: =IF(H8="",(""),IF(H8="DP",(J7+G8),IF(H8="DB",(J7-G8),IF(H8="TR",(J7-G8),IF(H8="CH",(J7-G8),IF(H8="SQ",(J7-G8),J7)))))) | K8: =IF(H8="",(""),IF(H8="SQ",(K7+G8),IF(H8="RD",(K7+G8),IF(H8="DI",(K7-G8),K7)))) | L8: =IF(H8="",(""),IF(H8="CC",(L7+G8),IF(H8="PC",(L7+G8),L7)))
B9: =IF(IF(ISERROR(VLOOKUP(D9,Categorias!$B$4:$C$65,2,FALSE)),"",VLOOKUP(D9,Categorias!$B$4:$C$65,2,FALSE))=D9,"",VLOOKUP(D9,(Categorias!$B$4:$C$65),2,FALSE)) | C9: =IF(IF(ISERROR(VLOOKUP(D9,Categorias!$B$4:$C$65,2,FALSE)),"",VLOOKUP(D9,Categorias!$B$4:$C$65,2,FALSE))=D9,"",VLOOKUP(D9,(Categorias!$B$2:$D$65),3,FALSE)) | J9: =IF(H9="",(""),IF(H9="DP",(J8+G9),IF(H9="DB",(J8-G9),IF(H9="TR",(J8-G9),IF(H9="CH",(J8-G9),IF(H9="SQ",(J8-G9),J8)))))) | K9: =IF(H9="",(""),IF(H9="SQ",(K8+G9),IF(H9="RD",(K8+G9),IF(H9="DI",(K8-G9),K8)))) | L9: =IF(H9="",(""),IF(H9="CC",(L8+G9),IF(H9="PC",(L8+G9),L8)))
B10: =IF(IF(ISERROR(VLOOKUP(D10,Categorias!$B$4:$C$65,2,FALSE)),"",VLOOKUP(D10,Categorias!$B$4:$C$65,2,FALSE))=D10,"",VLOOKUP(D10,(Categorias!$B$4:$C$65),2,FALSE)) | C10: =IF(IF(ISERROR(VLOOKUP(D10,Categorias!$B$4:$C$65,2,FALSE)),"",VLOOKUP(D10,Categorias!$B$4:$C$65,2,FALSE))=D10,"",VLOOKUP(D10,(Categorias!$B$2:$D$65),3,FALSE)) | J10: =IF(H10="",(""),IF(H10="DP",(J9+G10),IF(H10="DB",(J9-G10),IF(H10="TR",(J9-G10),IF(H10="CH",(J9-G10),IF(H10="SQ",(J9-G10),J9)))))) | K10: =IF(H10="",(""),IF(H10="SQ",(K9+G10),IF(H10="RD",(K9+G10),IF(H10="DI",(K9-G10),K9)))) | L10: =IF(H10="",(""),IF(H10="CC",(L9+G10),IF(H10="PC",(L9+G10),L9)))
B11: =IF(IF(ISERROR(VLOOKUP(D11,Categorias!$B$4:$C$65,2,FALSE)),"",VLOOKUP(D11,Categorias!$B$4:$C$65,2,FALSE))=D11,"",VLOOKUP(D11,(Categorias!$B$4:$C$65),2,FALSE)) | C11: =IF(IF(ISERROR(VLOOKUP(D11,Categorias!$B$4:$C$65,2,FALSE)),"",VLOOKUP(D11,Categorias!$B$4:$C$65,2,FALSE))=D11,"",VLOOKUP(D11,(Categorias!$B$2:$D$65),3,FALSE)) | J11: =IF(H11="",(""),IF(H11="DP",(J10+G11),IF(H11="DB",(J10-G11),IF(H11="TR",(J10-G11),IF(H11="CH",(J10-G11),IF(H11="SQ",(J10-G11),J10)))))) | K11: =IF(H11="",(""),IF(H11="SQ",(K10+G11),IF(H11="RD",(K10+G11),IF(H11="DI",(K10-G11),K10)))) | L11: =IF(H11="",(""),IF(H11="CC",(L10+G11),IF(H11="PC",(L10+G11),L10)))
B12: =IF(IF(ISERROR(VLOOKUP(D12,Categorias!$B$4:$C$65,2,FALSE)),"",VLOOKUP(D12,Categorias!$B$4:$C$65,2,FALSE))=D12,"",VLOOKUP(D12,(Categorias!$B$4:$C$65),2,FALSE)) | C12: =IF(IF(ISERROR(VLOOKUP(D12,Categorias!$B$4:$C$65,2,FALSE)),"",VLOOKUP(D12,Categorias!$B$4:$C$65,2,FALSE))=D12,"",VLOOKUP(D12,(Categorias!$B$2:$D$65),3,FALSE)) | J12: =IF(H12="",(""),IF(H12="DP",(J11+G12),IF(H12="DB",(J11-G12),IF(H12="TR",(J11-G12),IF(H12="CH",(J11-G12),IF(H12="SQ",(J11-G12),J11)))))) | K12: =IF(H12="",(""),IF(H12="SQ",(K11+G12),IF(H12="RD",(K11+G12),IF(H12="DI",(K11-G12),K11)))) | L12: =IF(H12="",(""),IF(H12="CC",(L11+G12),IF(H12="PC",(L11+G12),L11)))
B13: =IF(IF(ISERROR(VLOOKUP(D13,Categorias!$B$4:$C$65,2,FALSE)),"",VLOOKUP(D13,Categorias!$B$4:$C$65,2,FALSE))=D13,"",VLOOKUP(D13,(Categorias!$B$4:$C$65),2,FALSE)) | C13: =IF(IF(ISERROR(VLOOKUP(D13,Categorias!$B$4:$C$65,2,FALSE)),"",VLOOKUP(D13,Categorias!$B$4:$C$65,2,FALSE))=D13,"",VLOOKUP(D13,(Categorias!$B$2:$D$65),3,FALSE)) | J13: =IF(H13="",(""),IF(H13="DP",(J12+G13),IF(H13="DB",(J12-G13),IF(H13="TR",(J12-G13),IF(H13="CH",(J12-G13),IF(H13="SQ",(J12-G13),J12)))))) | K13: =IF(H13="",(""),IF(H13="SQ",(K12+G13),IF(H13="RD",(K12+G13),IF(H13="DI",(K12-G13),K12)))) | L13: =IF(H13="",(""),IF(H13="CC",(L12+G13),IF(H13="PC",(L12+G13),L12)))
B14: =IF(IF(ISERROR(VLOOKUP(D14,Categorias!$B$4:$C$65,2,FALSE)),"",VLOOKUP(D14,Categorias!$B$4:$C$65,2,FALSE))=D14,"",VLOOKUP(D14,(Categorias!$B$4:$C$65),2,FALSE)) | C14: =IF(IF(ISERROR(VLOOKUP(D14,Categorias!$B$4:$C$65,2,FALSE)),"",VLOOKUP(D14,Categorias!$B$4:$C$65,2,FALSE))=D14,"",VLOOKUP(D14,(Categorias!$B$2:$D$65),3,FALSE)) | J14: =IF(H14="",(""),IF(H14="DP",(J13+G14),IF(H14="DB",(J13-G14),IF(H14="TR",(J13-G14),IF(H14="CH",(J13-G14),IF(H14="SQ",(J13-G14),J13)))))) | K14: =IF(H14="",(""),IF(H14="SQ",(K13+G14),IF(H14="RD",(K13+G14),IF(H14="DI",(K13-G14),K13)))) | L14: =IF(H14="",(""),IF(H14="CC",(L13+G14),IF(H14="PC",(L13+G14),L13)))
B15: =IF(IF(ISERROR(VLOOKUP(D15,Categorias!$B$4:$C$65,2,FALSE)),"",VLOOKUP(D15,Categorias!$B$4:$C$65,2,FALSE))=D15,"",VLOOKUP(D15,(Categorias!$B$4:$C$65),2,FALSE)) | C15: =IF(IF(ISERROR(VLOOKUP(D15,Categorias!$B$4:$C$65,2,FALSE)),"",VLOOKUP(D15,Categorias!$B$4:$C$65,2,FALSE))=D15,"",VLOOKUP(D15,(Categorias!$B$2:$D$65),3,FALSE)) | J15: =IF(H15="",(""),IF(H15="DP",(J14+G15),IF(H15="DB",(J14-G15),IF(H15="TR",(J14-G15),IF(H15="CH",(J14-G15),IF(H15="SQ",(J14-G15),J14)))))) | K15: =IF(H15="",(""),IF(H15="SQ",(K14+G15),IF(H15="RD",(K14+G15),IF(H15="DI",(K14-G15),K14)))) | L15: =IF(H15="",(""),IF(H15="CC",(L14+G15),IF(H15="PC",(L14+G15),L14)))
B16: =IF(IF(ISERROR(VLOOKUP(D16,Categorias!$B$4:$C$65,2,FALSE)),"",VLOOKUP(D16,Categorias!$B$4:$C$65,2,FALSE))=D16,"",VLOOKUP(D16,(Categorias!$B$4:$C$65),2,FALSE)) | C16: =IF(IF(ISERROR(VLOOKUP(D16,Categorias!$B$4:$C$65,2,FALSE)),"",VLOOKUP(D16,Categorias!$B$4:$C$65,2,FALSE))=D16,"",VLOOKUP(D16,(Categorias!$B$2:$D$65),3,FALSE)) | J16: =IF(H16="",(""),IF(H16="DP",(J15+G16),IF(H16="DB",(J15-G16),IF(H16="TR",(J15-G16),IF(H16="CH",(J15-G16),IF(H16="SQ",(J15-G16),J15)))))) | K16: =IF(H16="",(""),IF(H16="SQ",(K15+G16),IF(H16="RD",(K15+G16),IF(H16="DI",(K15-G16),K15)))) | L16: =IF(H16="",(""),IF(H16="CC",(L15+G16),IF(H16="PC",(L15+G16),L15)))
B17: =IF(IF(ISERROR(VLOOKUP(D17,Categorias!$B$4:$C$65,2,FALSE)),"",VLOOKUP(D17,Categorias!$B$4:$C$65,2,FALSE))=D17,"",VLOOKUP(D17,(Categorias!$B$4:$C$65),2,FALSE)) | C17: =IF(IF(ISERROR(VLOOKUP(D17,Categorias!$B$4:$C$65,2,FALSE)),"",VLOOKUP(D17,Categorias!$B$4:$C$65,2,FALSE))=D17,"",VLOOKUP(D17,(Categorias!$B$2:$D$65),3,FALSE)) | J17: =IF(H17="",(""),IF(H17="DP",(J16+G17),IF(H17="DB",(J16-G17),IF(H17="TR",(J16-G17),IF(H17="CH",(J16-G17),IF(H17="SQ",(J16-G17),J16)))))) | K17: =IF(H17="",(""),IF(H17="SQ",(K16+G17),IF(H17="RD",(K16+G17),IF(H17="DI",(K16-G17),K16)))) | L17: =IF(H17="",(""),IF(H17="CC",(L16+G17),IF(H17="PC",(L16+G17),L16)))
B18: =IF(IF(ISERROR(VLOOKUP(D18,Categorias!$B$4:$C$65,2,FALSE)),"",VLOOKUP(D18,Categorias!$B$4:$C$65,2,FALSE))=D18,"",VLOOKUP(D18,(Categorias!$B$4:$C$65),2,FALSE)) | C18: =IF(IF(ISERROR(VLOOKUP(D18,Categorias!$B$4:$C$65,2,FALSE)),"",VLOOKUP(D18,Categorias!$B$4:$C$65,2,FALSE))=D18,"",VLOOKUP(D18,(Categorias!$B$2:$D$65),3,FALSE)) | J18: =IF(H18="",(""),IF(H18="DP",(J17+G18),IF(H18="DB",(J17-G18),IF(H18="TR",(J17-G18),IF(H18="CH",(J17-G18),IF(H18="SQ",(J17-G18),J17)))))) | K18: =IF(H18="",(""),IF(H18="SQ",(K17+G18),IF(H18="RD",(K17+G18),IF(H18="DI",(K17-G18),K17)))) | L18: =IF(H18="",(""),IF(H18="CC",(L17+G18),IF(H18="PC",(L17+G18),L17)))
... B75: =IF(IF(ISERROR(VLOOKUP(D75,Categorias!$B$4:$C$65,2,FALSE)),"",VLOOKUP(D75,Categorias!$B$4:$C$65,2,FALSE))=D75,"",VLOOKUP(D75,(Categorias!$B$4:$C$65),2,FALSE)) | C75: =IF(IF(ISERROR(VLOOKUP(D75,Categorias!$B$4:$C$65,2,FALSE)),"",VLOOKUP(D75,Categorias!$B$4:$C$65,2,FALSE))=D75,"",VLOOKUP(D75,(Categorias!$B$2:$D$65),3,FALSE)) | J75: =IF(H75="",(""),IF(H75="DP",(J74+G75),IF(H75="DB",(J74-G75),IF(H75="TR",(J74-G75),IF(H75="CH",(J74-G75),IF(H75="SQ",(J74-G75),J74)))))) | K75: =IF(H75="",(""),IF(H75="SQ",(K74+G75),IF(H75="RD",(K74+G75),IF(H75="DI",(K74-G75),K74)))) | L75: =IF(H75="",(""),IF(H75="CC",(L74+G75),IF(H75="PC",(L74+G75),L74)))
F76: Saldo no mês | J76: =+J75 | K76: =+K75 | L76: =+L75
A213: 1
A214: 1

Sheet Abr
C1: Orçamento Doméstico
B2: Descritivo de Receitas e Despesas realizadas | F2: Abril | H2: =+'Instruções'!$I$19 -> #REF! | J2: Movimentação do saldo no mês
H3: Meio de pagamento | J3: Saldo do mês anterior
B4: Grupo de conta | C4: Sub-grupo de conta | D4: Cod. | E4: Data | F4: Descritivo | G4: Valor R$ | J4: C.Corrente (+ / -) | K4: Dinheiro (+ / -) | L4: C. de Crédito (+)
A6: 1 | B6: =IF(IF(ISERROR(VLOOKUP(D6,Categorias!$B$4:$C$65,2,FALSE)),"",VLOOKUP(D6,Categorias!$B$4:$C$65,2,FALSE))=D6,"",VLOOKUP(D6,(Categorias!$B$4:$C$65),2,FALSE)) | C6: =IF(IF(ISERROR(VLOOKUP(D6,Categorias!$B$4:$C$65,2,FALSE)),"",VLOOKUP(D6,Categorias!$B$4:$C$65,2,FALSE))=D6,"",VLOOKUP(D6,(Categorias!$B$2:$D$65),3,FALSE)) | J6: =IF(H6="",(""),IF(H6="DP",(J5+G6),IF(H6="DB",(J5-G6),IF(H6="TR",(J5-G6),IF(H6="CH",(J5-G6),IF(H6="SQ",(J5-G6),J5)))))) | K6: =IF(H6="",(""),IF(H6="SQ",(K5+G6),IF(H6="RD",(K5+G6),IF(H6="DI",(K5-G6),K5)))) | L6: =IF(H6="",(""),IF(H6="CC",(L5+G6),IF(H6="PC",(L5+G6),L5)))
B7: =IF(IF(ISERROR(VLOOKUP(D7,Categorias!$B$4:$C$65,2,FALSE)),"",VLOOKUP(D7,Categorias!$B$4:$C$65,2,FALSE))=D7,"",VLOOKUP(D7,(Categorias!$B$4:$C$65),2,FALSE)) | C7: =IF(IF(ISERROR(VLOOKUP(D7,Categorias!$B$4:$C$65,2,FALSE)),"",VLOOKUP(D7,Categorias!$B$4:$C$65,2,FALSE))=D7,"",VLOOKUP(D7,(Categorias!$B$2:$D$65),3,FALSE)) | J7: =IF(H7="",(""),IF(H7="DP",(J6+G7),IF(H7="DB",(J6-G7),IF(H7="TR",(J6-G7),IF(H7="CH",(J6-G7),IF(H7="SQ",(J6-G7),J6)))))) | K7: =IF(H7="",(""),IF(H7="SQ",(K6+G7),IF(H7="RD",(K6+G7),IF(H7="DI",(K6-G7),K6)))) | L7: =IF(H7="",(""),IF(H7="CC",(L6+G7),IF(H7="PC",(L6+G7),L6)))
B8: =IF(IF(ISERROR(VLOOKUP(D8,Categorias!$B$4:$C$65,2,FALSE)),"",VLOOKUP(D8,Categorias!$B$4:$C$65,2,FALSE))=D8,"",VLOOKUP(D8,(Categorias!$B$4:$C$65),2,FALSE)) | C8: =IF(IF(ISERROR(VLOOKUP(D8,Categorias!$B$4:$C$65,2,FALSE)),"",VLOOKUP(D8,Categorias!$B$4:$C$65,2,FALSE))=D8,"",VLOOKUP(D8,(Categorias!$B$2:$D$65),3,FALSE)) | J8: =IF(H8="",(""),IF(H8="DP",(J7+G8),IF(H8="DB",(J7-G8),IF(H8="TR",(J7-G8),IF(H8="CH",(J7-G8),IF(H8="SQ",(J7-G8),J7)))))) | K8: =IF(H8="",(""),IF(H8="SQ",(K7+G8),IF(H8="RD",(K7+G8),IF(H8="DI",(K7-G8),K7)))) | L8: =IF(H8="",(""),IF(H8="CC",(L7+G8),IF(H8="PC",(L7+G8),L7)))
B9: =IF(IF(ISERROR(VLOOKUP(D9,Categorias!$B$4:$C$65,2,FALSE)),"",VLOOKUP(D9,Categorias!$B$4:$C$65,2,FALSE))=D9,"",VLOOKUP(D9,(Categorias!$B$4:$C$65),2,FALSE)) | C9: =IF(IF(ISERROR(VLOOKUP(D9,Categorias!$B$4:$C$65,2,FALSE)),"",VLOOKUP(D9,Categorias!$B$4:$C$65,2,FALSE))=D9,"",VLOOKUP(D9,(Categorias!$B$2:$D$65),3,FALSE)) | J9: =IF(H9="",(""),IF(H9="DP",(J8+G9),IF(H9="DB",(J8-G9),IF(H9="TR",(J8-G9),IF(H9="CH",(J8-G9),IF(H9="SQ",(J8-G9),J8)))))) | K9: =IF(H9="",(""),IF(H9="SQ",(K8+G9),IF(H9="RD",(K8+G9),IF(H9="DI",(K8-G9),K8)))) | L9: =IF(H9="",(""),IF(H9="CC",(L8+G9),IF(H9="PC",(L8+G9),L8)))
B10: =IF(IF(ISERROR(VLOOKUP(D10,Categorias!$B$4:$C$65,2,FALSE)),"",VLOOKUP(D10,Categorias!$B$4:$C$65,2,FALSE))=D10,"",VLOOKUP(D10,(Categorias!$B$4:$C$65),2,FALSE)) | C10: =IF(IF(ISERROR(VLOOKUP(D10,Categorias!$B$4:$C$65,2,FALSE)),"",VLOOKUP(D10,Categorias!$B$4:$C$65,2,FALSE))=D10,"",VLOOKUP(D10,(Categorias!$B$2:$D$65),3,FALSE)) | J10: =IF(H10="",(""),IF(H10="DP",(J9+G10),IF(H10="DB",(J9-G10),IF(H10="TR",(J9-G10),IF(H10="CH",(J9-G10),IF(H10="SQ",(J9-G10),J9)))))) | K10: =IF(H10="",(""),IF(H10="SQ",(K9+G10),IF(H10="RD",(K9+G10),IF(H10="DI",(K9-G10),K9)))) | L10: =IF(H10="",(""),IF(H10="CC",(L9+G10),IF(H10="PC",(L9+G10),L9)))
B11: =IF(IF(ISERROR(VLOOKUP(D11,Categorias!$B$4:$C$65,2,FALSE)),"",VLOOKUP(D11,Categorias!$B$4:$C$65,2,FALSE))=D11,"",VLOOKUP(D11,(Categorias!$B$4:$C$65),2,FALSE)) | C11: =IF(IF(ISERROR(VLOOKUP(D11,Categorias!$B$4:$C$65,2,FALSE)),"",VLOOKUP(D11,Categorias!$B$4:$C$65,2,FALSE))=D11,"",VLOOKUP(D11,(Categorias!$B$2:$D$65),3,FALSE)) | J11: =IF(H11="",(""),IF(H11="DP",(J10+G11),IF(H11="DB",(J10-G11),IF(H11="TR",(J10-G11),IF(H11="CH",(J10-G11),IF(H11="SQ",(J10-G11),J10)))))) | K11: =IF(H11="",(""),IF(H11="SQ",(K10+G11),IF(H11="RD",(K10+G11),IF(H11="DI",(K10-G11),K10)))) | L11: =IF(H11="",(""),IF(H11="CC",(L10+G11),IF(H11="PC",(L10+G11),L10)))
B12: =IF(IF(ISERROR(VLOOKUP(D12,Categorias!$B$4:$C$65,2,FALSE)),"",VLOOKUP(D12,Categorias!$B$4:$C$65,2,FALSE))=D12,"",VLOOKUP(D12,(Categorias!$B$4:$C$65),2,FALSE)) | C12: =IF(IF(ISERROR(VLOOKUP(D12,Categorias!$B$4:$C$65,2,FALSE)),"",VLOOKUP(D12,Categorias!$B$4:$C$65,2,FALSE))=D12,"",VLOOKUP(D12,(Categorias!$B$2:$D$65),3,FALSE)) | J12: =IF(H12="",(""),IF(H12="DP",(J11+G12),IF(H12="DB",(J11-G12),IF(H12="TR",(J11-G12),IF(H12="CH",(J11-G12),IF(H12="SQ",(J11-G12),J11)))))) | K12: =IF(H12="",(""),IF(H12="SQ",(K11+G12),IF(H12="RD",(K11+G12),IF(H12="DI",(K11-G12),K11)))) | L12: =IF(H12="",(""),IF(H12="CC",(L11+G12),IF(H12="PC",(L11+G12),L11)))
B13: =IF(IF(ISERROR(VLOOKUP(D13,Categorias!$B$4:$C$65,2,FALSE)),"",VLOOKUP(D13,Categorias!$B$4:$C$65,2,FALSE))=D13,"",VLOOKUP(D13,(Categorias!$B$4:$C$65),2,FALSE)) | C13: =IF(IF(ISERROR(VLOOKUP(D13,Categorias!$B$4:$C$65,2,FALSE)),"",VLOOKUP(D13,Categorias!$B$4:$C$65,2,FALSE))=D13,"",VLOOKUP(D13,(Categorias!$B$2:$D$65),3,FALSE)) | J13: =IF(H13="",(""),IF(H13="DP",(J12+G13),IF(H13="DB",(J12-G13),IF(H13="TR",(J12-G13),IF(H13="CH",(J12-G13),IF(H13="SQ",(J12-G13),J12)))))) | K13: =IF(H13="",(""),IF(H13="SQ",(K12+G13),IF(H13="RD",(K12+G13),IF(H13="DI",(K12-G13),K12)))) | L13: =IF(H13="",(""),IF(H13="CC",(L12+G13),IF(H13="PC",(L12+G13),L12)))
B14: =IF(IF(ISERROR(VLOOKUP(D14,Categorias!$B$4:$C$65,2,FALSE)),"",VLOOKUP(D14,Categorias!$B$4:$C$65,2,FALSE))=D14,"",VLOOKUP(D14,(Categorias!$B$4:$C$65),2,FALSE)) | C14: =IF(IF(ISERROR(VLOOKUP(D14,Categorias!$B$4:$C$65,2,FALSE)),"",VLOOKUP(D14,Categorias!$B$4:$C$65,2,FALSE))=D14,"",VLOOKUP(D14,(Categorias!$B$2:$D$65),3,FALSE)) | J14: =IF(H14="",(""),IF(H14="DP",(J13+G14),IF(H14="DB",(J13-G14),IF(H14="TR",(J13-G14),IF(H14="CH",(J13-G14),IF(H14="SQ",(J13-G14),J13)))))) | K14: =IF(H14="",(""),IF(H14="SQ",(K13+G14),IF(H14="RD",(K13+G14),IF(H14="DI",(K13-G14),K13)))) | L14: =IF(H14="",(""),IF(H14="CC",(L13+G14),IF(H14="PC",(L13+G14),L13)))
B15: =IF(IF(ISERROR(VLOOKUP(D15,Categorias!$B$4:$C$65,2,FALSE)),"",VLOOKUP(D15,Categorias!$B$4:$C$65,2,FALSE))=D15,"",VLOOKUP(D15,(Categorias!$B$4:$C$65),2,FALSE)) | C15: =IF(IF(ISERROR(VLOOKUP(D15,Categorias!$B$4:$C$65,2,FALSE)),"",VLOOKUP(D15,Categorias!$B$4:$C$65,2,FALSE))=D15,"",VLOOKUP(D15,(Categorias!$B$2:$D$65),3,FALSE)) | J15: =IF(H15="",(""),IF(H15="DP",(J14+G15),IF(H15="DB",(J14-G15),IF(H15="TR",(J14-G15),IF(H15="CH",(J14-G15),IF(H15="SQ",(J14-G15),J14)))))) | K15: =IF(H15="",(""),IF(H15="SQ",(K14+G15),IF(H15="RD",(K14+G15),IF(H15="DI",(K14-G15),K14)))) | L15: =IF(H15="",(""),IF(H15="CC",(L14+G15),IF(H15="PC",(L14+G15),L14)))
B16: =IF(IF(ISERROR(VLOOKUP(D16,Categorias!$B$4:$C$65,2,FALSE)),"",VLOOKUP(D16,Categorias!$B$4:$C$65,2,FALSE))=D16,"",VLOOKUP(D16,(Categorias!$B$4:$C$65),2,FALSE)) | C16: =IF(IF(ISERROR(VLOOKUP(D16,Categorias!$B$4:$C$65,2,FALSE)),"",VLOOKUP(D16,Categorias!$B$4:$C$65,2,FALSE))=D16,"",VLOOKUP(D16,(Categorias!$B$2:$D$65),3,FALSE)) | J16: =IF(H16="",(""),IF(H16="DP",(J15+G16),IF(H16="DB",(J15-G16),IF(H16="TR",(J15-G16),IF(H16="CH",(J15-G16),IF(H16="SQ",(J15-G16),J15)))))) | K16: =IF(H16="",(""),IF(H16="SQ",(K15+G16),IF(H16="RD",(K15+G16),IF(H16="DI",(K15-G16),K15)))) | L16: =IF(H16="",(""),IF(H16="CC",(L15+G16),IF(H16="PC",(L15+G16),L15)))
B17: =IF(IF(ISERROR(VLOOKUP(D17,Categorias!$B$4:$C$65,2,FALSE)),"",VLOOKUP(D17,Categorias!$B$4:$C$65,2,FALSE))=D17,"",VLOOKUP(D17,(Categorias!$B$4:$C$65),2,FALSE)) | C17: =IF(IF(ISERROR(VLOOKUP(D17,Categorias!$B$4:$C$65,2,FALSE)),"",VLOOKUP(D17,Categorias!$B$4:$C$65,2,FALSE))=D17,"",VLOOKUP(D17,(Categorias!$B$2:$D$65),3,FALSE)) | J17: =IF(H17="",(""),IF(H17="DP",(J16+G17),IF(H17="DB",(J16-G17),IF(H17="TR",(J16-G17),IF(H17="CH",(J16-G17),IF(H17="SQ",(J16-G17),J16)))))) | K17: =IF(H17="",(""),IF(H17="SQ",(K16+G17),IF(H17="RD",(K16+G17),IF(H17="DI",(K16-G17),K16)))) | L17: =IF(H17="",(""),IF(H17="CC",(L16+G17),IF(H17="PC",(L16+G17),L16)))
B18: =IF(IF(ISERROR(VLOOKUP(D18,Categorias!$B$4:$C$65,2,FALSE)),"",VLOOKUP(D18,Categorias!$B$4:$C$65,2,FALSE))=D18,"",VLOOKUP(D18,(Categorias!$B$4:$C$65),2,FALSE)) | C18: =IF(IF(ISERROR(VLOOKUP(D18,Categorias!$B$4:$C$65,2,FALSE)),"",VLOOKUP(D18,Categorias!$B$4:$C$65,2,FALSE))=D18,"",VLOOKUP(D18,(Categorias!$B$2:$D$65),3,FALSE)) | J18: =IF(H18="",(""),IF(H18="DP",(J17+G18),IF(H18="DB",(J17-G18),IF(H18="TR",(J17-G18),IF(H18="CH",(J17-G18),IF(H18="SQ",(J17-G18),J17)))))) | K18: =IF(H18="",(""),IF(H18="SQ",(K17+G18),IF(H18="RD",(K17+G18),IF(H18="DI",(K17-G18),K17)))) | L18: =IF(H18="",(""),IF(H18="CC",(L17+G18),IF(H18="PC",(L17+G18),L17)))
... B75: =IF(IF(ISERROR(VLOOKUP(D75,Categorias!$B$4:$C$65,2,FALSE)),"",VLOOKUP(D75,Categorias!$B$4:$C$65,2,FALSE))=D75,"",VLOOKUP(D75,(Categorias!$B$4:$C$65),2,FALSE)) | C75: =IF(IF(ISERROR(VLOOKUP(D75,Categorias!$B$4:$C$65,2,FALSE)),"",VLOOKUP(D75,Categorias!$B$4:$C$65,2,FALSE))=D75,"",VLOOKUP(D75,(Categorias!$B$2:$D$65),3,FALSE)) | J75: =IF(H75="",(""),IF(H75="DP",(J74+G75),IF(H75="DB",(J74-G75),IF(H75="TR",(J74-G75),IF(H75="CH",(J74-G75),IF(H75="SQ",(J74-G75),J74)))))) | K75: =IF(H75="",(""),IF(H75="SQ",(K74+G75),IF(H75="RD",(K74+G75),IF(H75="DI",(K74-G75),K74)))) | L75: =IF(H75="",(""),IF(H75="CC",(L74+G75),IF(H75="PC",(L74+G75),L74)))
F76: Saldo no mês | J76: =+J75 | K76: =+K75 | L76: =+L75
A213: 1
A214: 1

Sheet Mai
C1: Orçamento Doméstico
B2: Descritivo de Receitas e Despesas realizadas | F2: Maio | H2: =+'Instruções'!$I$19 -> #REF! | J2: Movimentação do saldo no mês
H3: Meio de pagamento | J3: Saldo do mês anterior
B4: Grupo de conta | C4: Sub-grupo de conta | D4: Cod. | E4: Data | F4: Descritivo | G4: Valor R$ | J4: C.Corrente (+ / -) | K4: Dinheiro (+ / -) | L4: C. de Crédito (+)
A6: 1 | B6: =IF(IF(ISERROR(VLOOKUP(D6,Categorias!$B$4:$C$65,2,FALSE)),"",VLOOKUP(D6,Categorias!$B$4:$C$65,2,FALSE))=D6,"",VLOOKUP(D6,(Categorias!$B$4:$C$65),2,FALSE)) | C6: =IF(IF(ISERROR(VLOOKUP(D6,Categorias!$B$4:$C$65,2,FALSE)),"",VLOOKUP(D6,Categorias!$B$4:$C$65,2,FALSE))=D6,"",VLOOKUP(D6,(Categorias!$B$2:$D$65),3,FALSE)) | J6: =IF(H6="",(""),IF(H6="DP",(J5+G6),IF(H6="DB",(J5-G6),IF(H6="TR",(J5-G6),IF(H6="CH",(J5-G6),IF(H6="SQ",(J5-G6),J5)))))) | K6: =IF(H6="",(""),IF(H6="SQ",(K5+G6),IF(H6="RD",(K5+G6),IF(H6="DI",(K5-G6),K5)))) | L6: =IF(H6="",(""),IF(H6="CC",(L5+G6),IF(H6="PC",(L5+G6),L5)))
B7: =IF(IF(ISERROR(VLOOKUP(D7,Categorias!$B$4:$C$65,2,FALSE)),"",VLOOKUP(D7,Categorias!$B$4:$C$65,2,FALSE))=D7,"",VLOOKUP(D7,(Categorias!$B$4:$C$65),2,FALSE)) | C7: =IF(IF(ISERROR(VLOOKUP(D7,Categorias!$B$4:$C$65,2,FALSE)),"",VLOOKUP(D7,Categorias!$B$4:$C$65,2,FALSE))=D7,"",VLOOKUP(D7,(Categorias!$B$2:$D$65),3,FALSE)) | J7: =IF(H7="",(""),IF(H7="DP",(J6+G7),IF(H7="DB",(J6-G7),IF(H7="TR",(J6-G7),IF(H7="CH",(J6-G7),IF(H7="SQ",(J6-G7),J6)))))) | K7: =IF(H7="",(""),IF(H7="SQ",(K6+G7),IF(H7="RD",(K6+G7),IF(H7="DI",(K6-G7),K6)))) | L7: =IF(H7="",(""),IF(H7="CC",(L6+G7),IF(H7="PC",(L6+G7),L6)))
B8: =IF(IF(ISERROR(VLOOKUP(D8,Categorias!$B$4:$C$65,2,FALSE)),"",VLOOKUP(D8,Categorias!$B$4:$C$65,2,FALSE))=D8,"",VLOOKUP(D8,(Categorias!$B$4:$C$65),2,FALSE)) | C8: =IF(IF(ISERROR(VLOOKUP(D8,Categorias!$B$4:$C$65,2,FALSE)),"",VLOOKUP(D8,Categorias!$B$4:$C$65,2,FALSE))=D8,"",VLOOKUP(D8,(Categorias!$B$2:$D$65),3,FALSE)) | J8: =IF(H8="",(""),IF(H8="DP",(J7+G8),IF(H8="DB",(J7-G8),IF(H8="TR",(J7-G8),IF(H8="CH",(J7-G8),IF(H8="SQ",(J7-G8),J7)))))) | K8: =IF(H8="",(""),IF(H8="SQ",(K7+G8),IF(H8="RD",(K7+G8),IF(H8="DI",(K7-G8),K7)))) | L8: =IF(H8="",(""),IF(H8="CC",(L7+G8),IF(H8="PC",(L7+G8),L7)))
B9: =IF(IF(ISERROR(VLOOKUP(D9,Categorias!$B$4:$C$65,2,FALSE)),"",VLOOKUP(D9,Categorias!$B$4:$C$65,2,FALSE))=D9,"",VLOOKUP(D9,(Categorias!$B$4:$C$65),2,FALSE)) | C9: =IF(IF(ISERROR(VLOOKUP(D9,Categorias!$B$4:$C$65,2,FALSE)),"",VLOOKUP(D9,Categorias!$B$4:$C$65,2,FALSE))=D9,"",VLOOKUP(D9,(Categorias!$B$2:$D$65),3,FALSE)) | J9: =IF(H9="",(""),IF(H9="DP",(J8+G9),IF(H9="DB",(J8-G9),IF(H9="TR",(J8-G9),IF(H9="CH",(J8-G9),IF(H9="SQ",(J8-G9),J8)))))) | K9: =IF(H9="",(""),IF(H9="SQ",(K8+G9),IF(H9="RD",(K8+G9),IF(H9="DI",(K8-G9),K8)))) | L9: =IF(H9="",(""),IF(H9="CC",(L8+G9),IF(H9="PC",(L8+G9),L8)))
B10: =IF(IF(ISERROR(VLOOKUP(D10,Categorias!$B$4:$C$65,2,FALSE)),"",VLOOKUP(D10,Categorias!$B$4:$C$65,2,FALSE))=D10,"",VLOOKUP(D10,(Categorias!$B$4:$C$65),2,FALSE)) | C10: =IF(IF(ISERROR(VLOOKUP(D10,Categorias!$B$4:$C$65,2,FALSE)),"",VLOOKUP(D10,Categorias!$B$4:$C$65,2,FALSE))=D10,"",VLOOKUP(D10,(Categorias!$B$2:$D$65),3,FALSE)) | J10: =IF(H10="",(""),IF(H10="DP",(J9+G10),IF(H10="DB",(J9-G10),IF(H10="TR",(J9-G10),IF(H10="CH",(J9-G10),IF(H10="SQ",(J9-G10),J9)))))) | K10: =IF(H10="",(""),IF(H10="SQ",(K9+G10),IF(H10="RD",(K9+G10),IF(H10="DI",(K9-G10),K9)))) | L10: =IF(H10="",(""),IF(H10="CC",(L9+G10),IF(H10="PC",(L9+G10),L9)))
B11: =IF(IF(ISERROR(VLOOKUP(D11,Categorias!$B$4:$C$65,2,FALSE)),"",VLOOKUP(D11,Categorias!$B$4:$C$65,2,FALSE))=D11,"",VLOOKUP(D11,(Categorias!$B$4:$C$65),2,FALSE)) | C11: =IF(IF(ISERROR(VLOOKUP(D11,Categorias!$B$4:$C$65,2,FALSE)),"",VLOOKUP(D11,Categorias!$B$4:$C$65,2,FALSE))=D11,"",VLOOKUP(D11,(Categorias!$B$2:$D$65),3,FALSE)) | J11: =IF(H11="",(""),IF(H11="DP",(J10+G11),IF(H11="DB",(J10-G11),IF(H11="TR",(J10-G11),IF(H11="CH",(J10-G11),IF(H11="SQ",(J10-G11),J10)))))) | K11: =IF(H11="",(""),IF(H11="SQ",(K10+G11),IF(H11="RD",(K10+G11),IF(H11="DI",(K10-G11),K10)))) | L11: =IF(H11="",(""),IF(H11="CC",(L10+G11),IF(H11="PC",(L10+G11),L10)))
B12: =IF(IF(ISERROR(VLOOKUP(D12,Categorias!$B$4:$C$65,2,FALSE)),"",VLOOKUP(D12,Categorias!$B$4:$C$65,2,FALSE))=D12,"",VLOOKUP(D12,(Categorias!$B$4:$C$65),2,FALSE)) | C12: =IF(IF(ISERROR(VLOOKUP(D12,Categorias!$B$4:$C$65,2,FALSE)),"",VLOOKUP(D12,Categorias!$B$4:$C$65,2,FALSE))=D12,"",VLOOKUP(D12,(Categorias!$B$2:$D$65),3,FALSE)) | J12: =IF(H12="",(""),IF(H12="DP",(J11+G12),IF(H12="DB",(J11-G12),IF(H12="TR",(J11-G12),IF(H12="CH",(J11-G12),IF(H12="SQ",(J11-G12),J11)))))) | K12: =IF(H12="",(""),IF(H12="SQ",(K11+G12),IF(H12="RD",(K11+G12),IF(H12="DI",(K11-G12),K11)))) | L12: =IF(H12="",(""),IF(H12="CC",(L11+G12),IF(H12="PC",(L11+G12),L11)))
B13: =IF(IF(ISERROR(VLOOKUP(D13,Categorias!$B$4:$C$65,2,FALSE)),"",VLOOKUP(D13,Categorias!$B$4:$C$65,2,FALSE))=D13,"",VLOOKUP(D13,(Categorias!$B$4:$C$65),2,FALSE)) | C13: =IF(IF(ISERROR(VLOOKUP(D13,Categorias!$B$4:$C$65,2,FALSE)),"",VLOOKUP(D13,Categorias!$B$4:$C$65,2,FALSE))=D13,"",VLOOKUP(D13,(Categorias!$B$2:$D$65),3,FALSE)) | J13: =IF(H13="",(""),IF(H13="DP",(J12+G13),IF(H13="DB",(J12-G13),IF(H13="TR",(J12-G13),IF(H13="CH",(J12-G13),IF(H13="SQ",(J12-G13),J12)))))) | K13: =IF(H13="",(""),IF(H13="SQ",(K12+G13),IF(H13="RD",(K12+G13),IF(H13="DI",(K12-G13),K12)))) | L13: =IF(H13="",(""),IF(H13="CC",(L12+G13),IF(H13="PC",(L12+G13),L12)))
B14: =IF(IF(ISERROR(VLOOKUP(D14,Categorias!$B$4:$C$65,2,FALSE)),"",VLOOKUP(D14,Categorias!$B$4:$C$65,2,FALSE))=D14,"",VLOOKUP(D14,(Categorias!$B$4:$C$65),2,FALSE)) | C14: =IF(IF(ISERROR(VLOOKUP(D14,Categorias!$B$4:$C$65,2,FALSE)),"",VLOOKUP(D14,Categorias!$B$4:$C$65,2,FALSE))=D14,"",VLOOKUP(D14,(Categorias!$B$2:$D$65),3,FALSE)) | J14: =IF(H14="",(""),IF(H14="DP",(J13+G14),IF(H14="DB",(J13-G14),IF(H14="TR",(J13-G14),IF(H14="CH",(J13-G14),IF(H14="SQ",(J13-G14),J13)))))) | K14: =IF(H14="",(""),IF(H14="SQ",(K13+G14),IF(H14="RD",(K13+G14),IF(H14="DI",(K13-G14),K13)))) | L14: =IF(H14="",(""),IF(H14="CC",(L13+G14),IF(H14="PC",(L13+G14),L13)))
B15: =IF(IF(ISERROR(VLOOKUP(D15,Categorias!$B$4:$C$65,2,FALSE)),"",VLOOKUP(D15,Categorias!$B$4:$C$65,2,FALSE))=D15,"",VLOOKUP(D15,(Categorias!$B$4:$C$65),2,FALSE)) | C15: =IF(IF(ISERROR(VLOOKUP(D15,Categorias!$B$4:$C$65,2,FALSE)),"",VLOOKUP(D15,Categorias!$B$4:$C$65,2,FALSE))=D15,"",VLOOKUP(D15,(Categorias!$B$2:$D$65),3,FALSE)) | J15: =IF(H15="",(""),IF(H15="DP",(J14+G15),IF(H15="DB",(J14-G15),IF(H15="TR",(J14-G15),IF(H15="CH",(J14-G15),IF(H15="SQ",(J14-G15),J14)))))) | K15: =IF(H15="",(""),IF(H15="SQ",(K14+G15),IF(H15="RD",(K14+G15),IF(H15="DI",(K14-G15),K14)))) | L15: =IF(H15="",(""),IF(H15="CC",(L14+G15),IF(H15="PC",(L14+G15),L14)))
B16: =IF(IF(ISERROR(VLOOKUP(D16,Categorias!$B$4:$C$65,2,FALSE)),"",VLOOKUP(D16,Categorias!$B$4:$C$65,2,FALSE))=D16,"",VLOOKUP(D16,(Categorias!$B$4:$C$65),2,FALSE)) | C16: =IF(IF(ISERROR(VLOOKUP(D16,Categorias!$B$4:$C$65,2,FALSE)),"",VLOOKUP(D16,Categorias!$B$4:$C$65,2,FALSE))=D16,"",VLOOKUP(D16,(Categorias!$B$2:$D$65),3,FALSE)) | J16: =IF(H16="",(""),IF(H16="DP",(J15+G16),IF(H16="DB",(J15-G16),IF(H16="TR",(J15-G16),IF(H16="CH",(J15-G16),IF(H16="SQ",(J15-G16),J15)))))) | K16: =IF(H16="",(""),IF(H16="SQ",(K15+G16),IF(H16="RD",(K15+G16),IF(H16="DI",(K15-G16),K15)))) | L16: =IF(H16="",(""),IF(H16="CC",(L15+G16),IF(H16="PC",(L15+G16),L15)))
B17: =IF(IF(ISERROR(VLOOKUP(D17,Categorias!$B$4:$C$65,2,FALSE)),"",VLOOKUP(D17,Categorias!$B$4:$C$65,2,FALSE))=D17,"",VLOOKUP(D17,(Categorias!$B$4:$C$65),2,FALSE)) | C17: =IF(IF(ISERROR(VLOOKUP(D17,Categorias!$B$4:$C$65,2,FALSE)),"",VLOOKUP(D17,Categorias!$B$4:$C$65,2,FALSE))=D17,"",VLOOKUP(D17,(Categorias!$B$2:$D$65),3,FALSE)) | J17: =IF(H17="",(""),IF(H17="DP",(J16+G17),IF(H17="DB",(J16-G17),IF(H17="TR",(J16-G17),IF(H17="CH",(J16-G17),IF(H17="SQ",(J16-G17),J16)))))) | K17: =IF(H17="",(""),IF(H17="SQ",(K16+G17),IF(H17="RD",(K16+G17),IF(H17="DI",(K16-G17),K16)))) | L17: =IF(H17="",(""),IF(H17="CC",(L16+G17),IF(H17="PC",(L16+G17),L16)))
B18: =IF(IF(ISERROR(VLOOKUP(D18,Categorias!$B$4:$C$65,2,FALSE)),"",VLOOKUP(D18,Categorias!$B$4:$C$65,2,FALSE))=D18,"",VLOOKUP(D18,(Categorias!$B$4:$C$65),2,FALSE)) | C18: =IF(IF(ISERROR(VLOOKUP(D18,Categorias!$B$4:$C$65,2,FALSE)),"",VLOOKUP(D18,Categorias!$B$4:$C$65,2,FALSE))=D18,"",VLOOKUP(D18,(Categorias!$B$2:$D$65),3,FALSE)) | J18: =IF(H18="",(""),IF(H18="DP",(J17+G18),IF(H18="DB",(J17-G18),IF(H18="TR",(J17-G18),IF(H18="CH",(J17-G18),IF(H18="SQ",(J17-G18),J17)))))) | K18: =IF(H18="",(""),IF(H18="SQ",(K17+G18),IF(H18="RD",(K17+G18),IF(H18="DI",(K17-G18),K17)))) | L18: =IF(H18="",(""),IF(H18="CC",(L17+G18),IF(H18="PC",(L17+G18),L17)))
... B75: =IF(IF(ISERROR(VLOOKUP(D75,Categorias!$B$4:$C$65,2,FALSE)),"",VLOOKUP(D75,Categorias!$B$4:$C$65,2,FALSE))=D75,"",VLOOKUP(D75,(Categorias!$B$4:$C$65),2,FALSE)) | C75: =IF(IF(ISERROR(VLOOKUP(D75,Categorias!$B$4:$C$65,2,FALSE)),"",VLOOKUP(D75,Categorias!$B$4:$C$65,2,FALSE))=D75,"",VLOOKUP(D75,(Categorias!$B$2:$D$65),3,FALSE)) | J75: =IF(H75="",(""),IF(H75="DP",(J74+G75),IF(H75="DB",(J74-G75),IF(H75="TR",(J74-G75),IF(H75="CH",(J74-G75),IF(H75="SQ",(J74-G75),J74)))))) | K75: =IF(H75="",(""),IF(H75="SQ",(K74+G75),IF(H75="RD",(K74+G75),IF(H75="DI",(K74-G75),K74)))) | L75: =IF(H75="",(""),IF(H75="CC",(L74+G75),IF(H75="PC",(L74+G75),L74)))
F76: Saldo no mês | J76: =+J75 | K76: =+K75 | L76: =+L75
A213: 1
A214: 1

Sheet Jun
C1: Orçamento Doméstico
B2: Descritivo de Receitas e Despesas realizadas | F2: Junho | H2: =+'Instruções'!$I$19 -> #REF! | J2: Movimentação do saldo no mês
H3: Meio de pagamento | J3: Saldo do mês anterior
B4: Grupo de conta | C4: Sub-grupo de conta | D4: Cod. | E4: Data | F4: Descritivo | G4: Valor R$ | J4: C.Corrente (+ / -) | K4: Dinheiro (+ / -) | L4: C. de Crédito (+)
A6: 1 | B6: =IF(IF(ISERROR(VLOOKUP(D6,Categorias!$B$4:$C$65,2,FALSE)),"",VLOOKUP(D6,Categorias!$B$4:$C$65,2,FALSE))=D6,"",VLOOKUP(D6,(Categorias!$B$4:$C$65),2,FALSE)) | C6: =IF(IF(ISERROR(VLOOKUP(D6,Categorias!$B$4:$C$65,2,FALSE)),"",VLOOKUP(D6,Categorias!$B$4:$C$65,2,FALSE))=D6,"",VLOOKUP(D6,(Categorias!$B$2:$D$65),3,FALSE)) | J6: =IF(H6="",(""),IF(H6="DP",(J5+G6),IF(H6="DB",(J5-G6),IF(H6="TR",(J5-G6),IF(H6="CH",(J5-G6),IF(H6="SQ",(J5-G6),J5)))))) | K6: =IF(H6="",(""),IF(H6="SQ",(K5+G6),IF(H6="RD",(K5+G6),IF(H6="DI",(K5-G6),K5)))) | L6: =IF(H6="",(""),IF(H6="CC",(L5+G6),IF(H6="PC",(L5+G6),L5)))
B7: =IF(IF(ISERROR(VLOOKUP(D7,Categorias!$B$4:$C$65,2,FALSE)),"",VLOOKUP(D7,Categorias!$B$4:$C$65,2,FALSE))=D7,"",VLOOKUP(D7,(Categorias!$B$4:$C$65),2,FALSE)) | C7: =IF(IF(ISERROR(VLOOKUP(D7,Categorias!$B$4:$C$65,2,FALSE)),"",VLOOKUP(D7,Categorias!$B$4:$C$65,2,FALSE))=D7,"",VLOOKUP(D7,(Categorias!$B$2:$D$65),3,FALSE)) | J7: =IF(H7="",(""),IF(H7="DP",(J6+G7),IF(H7="DB",(J6-G7),IF(H7="TR",(J6-G7),IF(H7="CH",(J6-G7),IF(H7="SQ",(J6-G7),J6)))))) | K7: =IF(H7="",(""),IF(H7="SQ",(K6+G7),IF(H7="RD",(K6+G7),IF(H7="DI",(K6-G7),K6)))) | L7: =IF(H7="",(""),IF(H7="CC",(L6+G7),IF(H7="PC",(L6+G7),L6)))
B8: =IF(IF(ISERROR(VLOOKUP(D8,Categorias!$B$4:$C$65,2,FALSE)),"",VLOOKUP(D8,Categorias!$B$4:$C$65,2,FALSE))=D8,"",VLOOKUP(D8,(Categorias!$B$4:$C$65),2,FALSE)) | C8: =IF(IF(ISERROR(VLOOKUP(D8,Categorias!$B$4:$C$65,2,FALSE)),"",VLOOKUP(D8,Categorias!$B$4:$C$65,2,FALSE))=D8,"",VLOOKUP(D8,(Categorias!$B$2:$D$65),3,FALSE)) | J8: =IF(H8="",(""),IF(H8="DP",(J7+G8),IF(H8="DB",(J7-G8),IF(H8="TR",(J7-G8),IF(H8="CH",(J7-G8),IF(H8="SQ",(J7-G8),J7)))))) | K8: =IF(H8="",(""),IF(H8="SQ",(K7+G8),IF(H8="RD",(K7+G8),IF(H8="DI",(K7-G8),K7)))) | L8: =IF(H8="",(""),IF(H8="CC",(L7+G8),IF(H8="PC",(L7+G8),L7)))
B9: =IF(IF(ISERROR(VLOOKUP(D9,Categorias!$B$4:$C$65,2,FALSE)),"",VLOOKUP(D9,Categorias!$B$4:$C$65,2,FALSE))=D9,"",VLOOKUP(D9,(Categorias!$B$4:$C$65),2,FALSE)) | C9: =IF(IF(ISERROR(VLOOKUP(D9,Categorias!$B$4:$C$65,2,FALSE)),"",VLOOKUP(D9,Categorias!$B$4:$C$65,2,FALSE))=D9,"",VLOOKUP(D9,(Categorias!$B$2:$D$65),3,FALSE)) | J9: =IF(H9="",(""),IF(H9="DP",(J8+G9),IF(H9="DB",(J8-G9),IF(H9="TR",(J8-G9),IF(H9="CH",(J8-G9),IF(H9="SQ",(J8-G9),J8)))))) | K9: =IF(H9="",(""),IF(H9="SQ",(K8+G9),IF(H9="RD",(K8+G9),IF(H9="DI",(K8-G9),K8)))) | L9: =IF(H9="",(""),IF(H9="CC",(L8+G9),IF(H9="PC",(L8+G9),L8)))
B10: =IF(IF(ISERROR(VLOOKUP(D10,Categorias!$B$4:$C$65,2,FALSE)),"",VLOOKUP(D10,Categorias!$B$4:$C$65,2,FALSE))=D10,"",VLOOKUP(D10,(Categorias!$B$4:$C$65),2,FALSE)) | C10: =IF(IF(ISERROR(VLOOKUP(D10,Categorias!$B$4:$C$65,2,FALSE)),"",VLOOKUP(D10,Categorias!$B$4:$C$65,2,FALSE))=D10,"",VLOOKUP(D10,(Categorias!$B$2:$D$65),3,FALSE)) | J10: =IF(H10="",(""),IF(H10="DP",(J9+G10),IF(H10="DB",(J9-G10),IF(H10="TR",(J9-G10),IF(H10="CH",(J9-G10),IF(H10="SQ",(J9-G10),J9)))))) | K10: =IF(H10="",(""),IF(H10="SQ",(K9+G10),IF(H10="RD",(K9+G10),IF(H10="DI",(K9-G10),K9)))) | L10: =IF(H10="",(""),IF(H10="CC",(L9+G10),IF(H10="PC",(L9+G10),L9)))
B11: =IF(IF(ISERROR(VLOOKUP(D11,Categorias!$B$4:$C$65,2,FALSE)),"",VLOOKUP(D11,Categorias!$B$4:$C$65,2,FALSE))=D11,"",VLOOKUP(D11,(Categorias!$B$4:$C$65),2,FALSE)) | C11: =IF(IF(ISERROR(VLOOKUP(D11,Categorias!$B$4:$C$65,2,FALSE)),"",VLOOKUP(D11,Categorias!$B$4:$C$65,2,FALSE))=D11,"",VLOOKUP(D11,(Categorias!$B$2:$D$65),3,FALSE)) | J11: =IF(H11="",(""),IF(H11="DP",(J10+G11),IF(H11="DB",(J10-G11),IF(H11="TR",(J10-G11),IF(H11="CH",(J10-G11),IF(H11="SQ",(J10-G11),J10)))))) | K11: =IF(H11="",(""),IF(H11="SQ",(K10+G11),IF(H11="RD",(K10+G11),IF(H11="DI",(K10-G11),K10)))) | L11: =IF(H11="",(""),IF(H11="CC",(L10+G11),IF(H11="PC",(L10+G11),L10)))
B12: =IF(IF(ISERROR(VLOOKUP(D12,Categorias!$B$4:$C$65,2,FALSE)),"",VLOOKUP(D12,Categorias!$B$4:$C$65,2,FALSE))=D12,"",VLOOKUP(D12,(Categorias!$B$4:$C$65),2,FALSE)) | C12: =IF(IF(ISERROR(VLOOKUP(D12,Categorias!$B$4:$C$65,2,FALSE)),"",VLOOKUP(D12,Categorias!$B$4:$C$65,2,FALSE))=D12,"",VLOOKUP(D12,(Categorias!$B$2:$D$65),3,FALSE)) | J12: =IF(H12="",(""),IF(H12="DP",(J11+G12),IF(H12="DB",(J11-G12),IF(H12="TR",(J11-G12),IF(H12="CH",(J11-G12),IF(H12="SQ",(J11-G12),J11)))))) | K12: =IF(H12="",(""),IF(H12="SQ",(K11+G12),IF(H12="RD",(K11+G12),IF(H12="DI",(K11-G12),K11)))) | L12: =IF(H12="",(""),IF(H12="CC",(L11+G12),IF(H12="PC",(L11+G12),L11)))
B13: =IF(IF(ISERROR(VLOOKUP(D13,Categorias!$B$4:$C$65,2,FALSE)),"",VLOOKUP(D13,Categorias!$B$4:$C$65,2,FALSE))=D13,"",VLOOKUP(D13,(Categorias!$B$4:$C$65),2,FALSE)) | C13: =IF(IF(ISERROR(VLOOKUP(D13,Categorias!$B$4:$C$65,2,FALSE)),"",VLOOKUP(D13,Categorias!$B$4:$C$65,2,FALSE))=D13,"",VLOOKUP(D13,(Categorias!$B$2:$D$65),3,FALSE)) | J13: =IF(H13="",(""),IF(H13="DP",(J12+G13),IF(H13="DB",(J12-G13),IF(H13="TR",(J12-G13),IF(H13="CH",(J12-G13),IF(H13="SQ",(J12-G13),J12)))))) | K13: =IF(H13="",(""),IF(H13="SQ",(K12+G13),IF(H13="RD",(K12+G13),IF(H13="DI",(K12-G13),K12)))) | L13: =IF(H13="",(""),IF(H13="CC",(L12+G13),IF(H13="PC",(L12+G13),L12)))
B14: =IF(IF(ISERROR(VLOOKUP(D14,Categorias!$B$4:$C$65,2,FALSE)),"",VLOOKUP(D14,Categorias!$B$4:$C$65,2,FALSE))=D14,"",VLOOKUP(D14,(Categorias!$B$4:$C$65),2,FALSE)) | C14: =IF(IF(ISERROR(VLOOKUP(D14,Categorias!$B$4:$C$65,2,FALSE)),"",VLOOKUP(D14,Categorias!$B$4:$C$65,2,FALSE))=D14,"",VLOOKUP(D14,(Categorias!$B$2:$D$65),3,FALSE)) | J14: =IF(H14="",(""),IF(H14="DP",(J13+G14),IF(H14="DB",(J13-G14),IF(H14="TR",(J13-G14),IF(H14="CH",(J13-G14),IF(H14="SQ",(J13-G14),J13)))))) | K14: =IF(H14="",(""),IF(H14="SQ",(K13+G14),IF(H14="RD",(K13+G14),IF(H14="DI",(K13-G14),K13)))) | L14: =IF(H14="",(""),IF(H14="CC",(L13+G14),IF(H14="PC",(L13+G14),L13)))
B15: =IF(IF(ISERROR(VLOOKUP(D15,Categorias!$B$4:$C$65,2,FALSE)),"",VLOOKUP(D15,Categorias!$B$4:$C$65,2,FALSE))=D15,"",VLOOKUP(D15,(Categorias!$B$4:$C$65),2,FALSE)) | C15: =IF(IF(ISERROR(VLOOKUP(D15,Categorias!$B$4:$C$65,2,FALSE)),"",VLOOKUP(D15,Categorias!$B$4:$C$65,2,FALSE))=D15,"",VLOOKUP(D15,(Categorias!$B$2:$D$65),3,FALSE)) | J15: =IF(H15="",(""),IF(H15="DP",(J14+G15),IF(H15="DB",(J14-G15),IF(H15="TR",(J14-G15),IF(H15="CH",(J14-G15),IF(H15="SQ",(J14-G15),J14)))))) | K15: =IF(H15="",(""),IF(H15="SQ",(K14+G15),IF(H15="RD",(K14+G15),IF(H15="DI",(K14-G15),K14)))) | L15: =IF(H15="",(""),IF(H15="CC",(L14+G15),IF(H15="PC",(L14+G15),L14)))
B16: =IF(IF(ISERROR(VLOOKUP(D16,Categorias!$B$4:$C$65,2,FALSE)),"",VLOOKUP(D16,Categorias!$B$4:$C$65,2,FALSE))=D16,"",VLOOKUP(D16,(Categorias!$B$4:$C$65),2,FALSE)) | C16: =IF(IF(ISERROR(VLOOKUP(D16,Categorias!$B$4:$C$65,2,FALSE)),"",VLOOKUP(D16,Categorias!$B$4:$C$65,2,FALSE))=D16,"",VLOOKUP(D16,(Categorias!$B$2:$D$65),3,FALSE)) | J16: =IF(H16="",(""),IF(H16="DP",(J15+G16),IF(H16="DB",(J15-G16),IF(H16="TR",(J15-G16),IF(H16="CH",(J15-G16),IF(H16="SQ",(J15-G16),J15)))))) | K16: =IF(H16="",(""),IF(H16="SQ",(K15+G16),IF(H16="RD",(K15+G16),IF(H16="DI",(K15-G16),K15)))) | L16: =IF(H16="",(""),IF(H16="CC",(L15+G16),IF(H16="PC",(L15+G16),L15)))
B17: =IF(IF(ISERROR(VLOOKUP(D17,Categorias!$B$4:$C$65,2,FALSE)),"",VLOOKUP(D17,Categorias!$B$4:$C$65,2,FALSE))=D17,"",VLOOKUP(D17,(Categorias!$B$4:$C$65),2,FALSE)) | C17: =IF(IF(ISERROR(VLOOKUP(D17,Categorias!$B$4:$C$65,2,FALSE)),"",VLOOKUP(D17,Categorias!$B$4:$C$65,2,FALSE))=D17,"",VLOOKUP(D17,(Categorias!$B$2:$D$65),3,FALSE)) | J17: =IF(H17="",(""),IF(H17="DP",(J16+G17),IF(H17="DB",(J16-G17),IF(H17="TR",(J16-G17),IF(H17="CH",(J16-G17),IF(H17="SQ",(J16-G17),J16)))))) | K17: =IF(H17="",(""),IF(H17="SQ",(K16+G17),IF(H17="RD",(K16+G17),IF(H17="DI",(K16-G17),K16)))) | L17: =IF(H17="",(""),IF(H17="CC",(L16+G17),IF(H17="PC",(L16+G17),L16)))
B18: =IF(IF(ISERROR(VLOOKUP(D18,Categorias!$B$4:$C$65,2,FALSE)),"",VLOOKUP(D18,Categorias!$B$4:$C$65,2,FALSE))=D18,"",VLOOKUP(D18,(Categorias!$B$4:$C$65),2,FALSE)) | C18: =IF(IF(ISERROR(VLOOKUP(D18,Categorias!$B$4:$C$65,2,FALSE)),"",VLOOKUP(D18,Categorias!$B$4:$C$65,2,FALSE))=D18,"",VLOOKUP(D18,(Categorias!$B$2:$D$65),3,FALSE)) | J18: =IF(H18="",(""),IF(H18="DP",(J17+G18),IF(H18="DB",(J17-G18),IF(H18="TR",(J17-G18),IF(H18="CH",(J17-G18),IF(H18="SQ",(J17-G18),J17)))))) | K18: =IF(H18="",(""),IF(H18="SQ",(K17+G18),IF(H18="RD",(K17+G18),IF(H18="DI",(K17-G18),K17)))) | L18: =IF(H18="",(""),IF(H18="CC",(L17+G18),IF(H18="PC",(L17+G18),L17)))
... B75: =IF(IF(ISERROR(VLOOKUP(D75,Categorias!$B$4:$C$65,2,FALSE)),"",VLOOKUP(D75,Categorias!$B$4:$C$65,2,FALSE))=D75,"",VLOOKUP(D75,(Categorias!$B$4:$C$65),2,FALSE)) | C75: =IF(IF(ISERROR(VLOOKUP(D75,Categorias!$B$4:$C$65,2,FALSE)),"",VLOOKUP(D75,Categorias!$B$4:$C$65,2,FALSE))=D75,"",VLOOKUP(D75,(Categorias!$B$2:$D$65),3,FALSE)) | J75: =IF(H75="",(""),IF(H75="DP",(J74+G75),IF(H75="DB",(J74-G75),IF(H75="TR",(J74-G75),IF(H75="CH",(J74-G75),IF(H75="SQ",(J74-G75),J74)))))) | K75: =IF(H75="",(""),IF(H75="SQ",(K74+G75),IF(H75="RD",(K74+G75),IF(H75="DI",(K74-G75),K74)))) | L75: =IF(H75="",(""),IF(H75="CC",(L74+G75),IF(H75="PC",(L74+G75),L74)))
F76: Saldo no mês | J76: =+J75 | K76: =+K75 | L76: =+L75
A213: 1
A214: 1

Sheet Jul
C1: Orçamento Doméstico
B2: Descritivo de Receitas e Despesas realizadas | F2: Julho | H2: =+'Instruções'!$I$19 -> #REF! | J2: Movimentação do saldo no mês
H3: Meio de pagamento | J3: Saldo do mês anterior
B4: Grupo de conta | C4: Sub-grupo de conta | D4: Cod. | E4: Data | F4: Descritivo | G4: Valor R$ | J4: C.Corrente (+ / -) | K4: Dinheiro (+ / -) | L4: C. de Crédito (+)
A6: 1 | B6: =IF(IF(ISERROR(VLOOKUP(D6,Categorias!$B$4:$C$65,2,FALSE)),"",VLOOKUP(D6,Categorias!$B$4:$C$65,2,FALSE))=D6,"",VLOOKUP(D6,(Categorias!$B$4:$C$65),2,FALSE)) | C6: =IF(IF(ISERROR(VLOOKUP(D6,Categorias!$B$4:$C$65,2,FALSE)),"",VLOOKUP(D6,Categorias!$B$4:$C$65,2,FALSE))=D6,"",VLOOKUP(D6,(Categorias!$B$2:$D$65),3,FALSE)) | J6: =IF(H6="",(""),IF(H6="DP",(J5+G6),IF(H6="DB",(J5-G6),IF(H6="TR",(J5-G6),IF(H6="CH",(J5-G6),IF(H6="SQ",(J5-G6),J5)))))) | K6: =IF(H6="",(""),IF(H6="SQ",(K5+G6),IF(H6="RD",(K5+G6),IF(H6="DI",(K5-G6),K5)))) | L6: =IF(H6="",(""),IF(H6="CC",(L5+G6),IF(H6="PC",(L5+G6),L5)))
B7: =IF(IF(ISERROR(VLOOKUP(D7,Categorias!$B$4:$C$65,2,FALSE)),"",VLOOKUP(D7,Categorias!$B$4:$C$65,2,FALSE))=D7,"",VLOOKUP(D7,(Categorias!$B$4:$C$65),2,FALSE)) | C7: =IF(IF(ISERROR(VLOOKUP(D7,Categorias!$B$4:$C$65,2,FALSE)),"",VLOOKUP(D7,Categorias!$B$4:$C$65,2,FALSE))=D7,"",VLOOKUP(D7,(Categorias!$B$2:$D$65),3,FALSE)) | J7: =IF(H7="",(""),IF(H7="DP",(J6+G7),IF(H7="DB",(J6-G7),IF(H7="TR",(J6-G7),IF(H7="CH",(J6-G7),IF(H7="SQ",(J6-G7),J6)))))) | K7: =IF(H7="",(""),IF(H7="SQ",(K6+G7),IF(H7="RD",(K6+G7),IF(H7="DI",(K6-G7),K6)))) | L7: =IF(H7="",(""),IF(H7="CC",(L6+G7),IF(H7="PC",(L6+G7),L6)))
B8: =IF(IF(ISERROR(VLOOKUP(D8,Categorias!$B$4:$C$65,2,FALSE)),"",VLOOKUP(D8,Categorias!$B$4:$C$65,2,FALSE))=D8,"",VLOOKUP(D8,(Categorias!$B$4:$C$65),2,FALSE)) | C8: =IF(IF(ISERROR(VLOOKUP(D8,Categorias!$B$4:$C$65,2,FALSE)),"",VLOOKUP(D8,Categorias!$B$4:$C$65,2,FALSE))=D8,"",VLOOKUP(D8,(Categorias!$B$2:$D$65),3,FALSE)) | J8: =IF(H8="",(""),IF(H8="DP",(J7+G8),IF(H8="DB",(J7-G8),IF(H8="TR",(J7-G8),IF(H8="CH",(J7-G8),IF(H8="SQ",(J7-G8),J7)))))) | K8: =IF(H8="",(""),IF(H8="SQ",(K7+G8),IF(H8="RD",(K7+G8),IF(H8="DI",(K7-G8),K7)))) | L8: =IF(H8="",(""),IF(H8="CC",(L7+G8),IF(H8="PC",(L7+G8),L7)))
B9: =IF(IF(ISERROR(VLOOKUP(D9,Categorias!$B$4:$C$65,2,FALSE)),"",VLOOKUP(D9,Categorias!$B$4:$C$65,2,FALSE))=D9,"",VLOOKUP(D9,(Categorias!$B$4:$C$65),2,FALSE)) | C9: =IF(IF(ISERROR(VLOOKUP(D9,Categorias!$B$4:$C$65,2,FALSE)),"",VLOOKUP(D9,Categorias!$B$4:$C$65,2,FALSE))=D9,"",VLOOKUP(D9,(Categorias!$B$2:$D$65),3,FALSE)) | J9: =IF(H9="",(""),IF(H9="DP",(J8+G9),IF(H9="DB",(J8-G9),IF(H9="TR",(J8-G9),IF(H9="CH",(J8-G9),IF(H9="SQ",(J8-G9),J8)))))) | K9: =IF(H9="",(""),IF(H9="SQ",(K8+G9),IF(H9="RD",(K8+G9),IF(H9="DI",(K8-G9),K8)))) | L9: =IF(H9="",(""),IF(H9="CC",(L8+G9),IF(H9="PC",(L8+G9),L8)))
B10: =IF(IF(ISERROR(VLOOKUP(D10,Categorias!$B$4:$C$65,2,FALSE)),"",VLOOKUP(D10,Categorias!$B$4:$C$65,2,FALSE))=D10,"",VLOOKUP(D10,(Categorias!$B$4:$C$65),2,FALSE)) | C10: =IF(IF(ISERROR(VLOOKUP(D10,Categorias!$B$4:$C$65,2,FALSE)),"",VLOOKUP(D10,Categorias!$B$4:$C$65,2,FALSE))=D10,"",VLOOKUP(D10,(Categorias!$B$2:$D$65),3,FALSE)) | J10: =IF(H10="",(""),IF(H10="DP",(J9+G10),IF(H10="DB",(J9-G10),IF(H10="TR",(J9-G10),IF(H10="CH",(J9-G10),IF(H10="SQ",(J9-G10),J9)))))) | K10: =IF(H10="",(""),IF(H10="SQ",(K9+G10),IF(H10="RD",(K9+G10),IF(H10="DI",(K9-G10),K9)))) | L10: =IF(H10="",(""),IF(H10="CC",(L9+G10),IF(H10="PC",(L9+G10),L9)))
B11: =IF(IF(ISERROR(VLOOKUP(D11,Categorias!$B$4:$C$65,2,FALSE)),"",VLOOKUP(D11,Categorias!$B$4:$C$65,2,FALSE))=D11,"",VLOOKUP(D11,(Categorias!$B$4:$C$65),2,FALSE)) | C11: =IF(IF(ISERROR(VLOOKUP(D11,Categorias!$B$4:$C$65,2,FALSE)),"",VLOOKUP(D11,Categorias!$B$4:$C$65,2,FALSE))=D11,"",VLOOKUP(D11,(Categorias!$B$2:$D$65),3,FALSE)) | J11: =IF(H11="",(""),IF(H11="DP",(J10+G11),IF(H11="DB",(J10-G11),IF(H11="TR",(J10-G11),IF(H11="CH",(J10-G11),IF(H11="SQ",(J10-G11),J10)))))) | K11: =IF(H11="",(""),IF(H11="SQ",(K10+G11),IF(H11="RD",(K10+G11),IF(H11="DI",(K10-G11),K10)))) | L11: =IF(H11="",(""),IF(H11="CC",(L10+G11),IF(H11="PC",(L10+G11),L10)))
